Workbook

Sheet マスタ
A1: 従業員番号 | B1: 氏名 | C1: 所属 | D1: 基本給 | E1: 役職手当 | F1: 通勤手当
A2: 001 | B2: 山田 太郎 | C2: 営業部 | D2: 350000 | E2: 30000 | F2: 15000
A3: 002 | B3: 鈴木 花子 | C3: 経理部 | D3: 280000 | E3: 0 | F3: 10000
A4: 003 | B4: 田中 一郎 | C4: 総務部 | D4: 320000 | E4: 20000 | F4: 12000

Sheet 1月
A1: 給与台帳 1月分
A2: 会社名：株式会社サンプル | L2: 作成日：2026年1月
A3: 基本情報 | D3: 勤 怠 情 報 | I3: 支 給 項 目 | O3: 控 除 項 目 | V3: 差引 支給額
A4: 従業員 番号 | B4: 氏名 | C4: 所属 | D4: 所定 労働日数 | E4: 出勤 日数 | F4: 欠勤 日数 | G4: 有給 取得日数 | H4: 残業 時間 | I4: 基本給 | J4: 役職 手当 | K4: 残業 手当 | L4: 通勤 手当 | M4: その他 手当 | N4: 支給 合計 | O4: 健康 保険 | P4: 厚生 年金 | Q4: 雇用 保険 | R4: 所得税 | S4: 住民税 | T4: その他 控除 | U4: 控除 合計 | V4: 差引 支給額
A5: 001 | B5: =IF(A5="","",IFERROR(VLOOKUP(A5,'マスタ'!$A:$F,2,FALSE),"")) | C5: =IF(A5="","",IFERROR(VLOOKUP(A5,'マスタ'!$A:$F,3,FALSE),"")) | D5: 20 | E5: 20 | F5: 0 | G5: 0 | H5: 10 | I5: =IF(A5="",0,IFERROR(VLOOKUP(A5,'マスタ'!$A:$F,4,FALSE),0)) | J5: =IF(A5="",0,IFERROR(VLOOKUP(A5,'マスタ'!$A:$F,5,FALSE),0)) | K5: =IF(A5="",0,ROUND(I5/160*1.25*H5,0)) | L5: =IF(A5="",0,IFERROR(VLOOKUP(A5,'マスタ'!$A:$F,6,FALSE),0)) | M5: 0 | N5: =SUM(I5:M5) | O5: 17500 | P5: 32490 | Q5: 2100 | R5: 8500 | S5: 12000 | T5: 0 | U5: =SUM(O5:T5) | V5: =N5-U5
A6: 002 | B6: =IF(A6="","",IFERROR(VLOOKUP(A6,'マスタ'!$A:$F,2,FALSE),"")) | C6: =IF(A6="","",IFERROR(VLOOKUP(A6,'マスタ'!$A:$F,3,FALSE),"")) | D6: 20 | E6: 19 | F6: 1 | G6: 1 | H6: 5 | I6: =IF(A6="",0,IFERROR(VLOOKUP(A6,'マスタ'!$A:$F,4,FALSE),0)) | J6: =IF(A6="",0,IFERROR(VLOOKUP(A6,'マスタ'!$A:$F,5,FALSE),0)) | K6: =IF(A6="",0,ROUND(I6/160*1.25*H6,0)) | L6: =IF(A6="",0,IFERROR(VLOOKUP(A6,'マスタ'!$A:$F,6,FALSE),0)) | M6: 0 | N6: =SUM(I6:M6) | O6: 14000 | P6: 25990 | Q6: 1680 | R6: 5500 | S6: 9000 | T6: 0 | U6: =SUM(O6:T6) | V6: =N6-U6
A7: 003 | B7: =IF(A7="","",IFERROR(VLOOKUP(A7,'マスタ'!$A:$F,2,FALSE),"")) | C7: =IF(A7="","",IFERROR(VLOOKUP(A7,'マスタ'!$A:$F,3,FALSE),"")) | D7: 20 | E7: 20 | F7: 0 | G7: 2 | H7: 15 | I7: =IF(A7="",0,IFERROR(VLOOKUP(A7,'マスタ'!$A:$F,4,FALSE),0)) | J7: =IF(A7="",0,IFERROR(VLOOKUP(A7,'マスタ'!$A:$F,5,FALSE),0)) | K7: =IF(A7="",0,ROUND(I7/160*1.25*H7,0)) | L7: =IF(A7="",0,IFERROR(VLOOKUP(A7,'マスタ'!$A:$F,6,FALSE),0)) | M7: 0 | N7: =SUM(I7:M7) | O7: 16000 | P7: 29730 | Q7: 1920 | R7: 7000 | S7: 10500 | T7: 0 | U7: =SUM(O7:T7) | V7: =N7-U7
B8: =IF(A8="","",IFERROR(VLOOKUP(A8,'マスタ'!$A:$F,2,FALSE),"")) | C8: =IF(A8="","",IFERROR(VLOOKUP(A8,'マスタ'!$A:$F,3,FALSE),"")) | I8: =IF(A8="",0,IFERROR(VLOOKUP(A8,'マスタ'!$A:$F,4,FALSE),0)) | J8: =IF(A8="",0,IFERROR(VLOOKUP(A8,'マスタ'!$A:$F,5,FALSE),0)) | K8: =IF(A8="",0,ROUND(I8/160*1.25*H8,0)) | L8: =IF(A8="",0,IFERROR(VLOOKUP(A8,'マスタ'!$A:$F,6,FALSE),0)) | N8: =SUM(I8:M8) | U8: =SUM(O8:T8) | V8: =N8-U8
B9: =IF(A9="","",IFERROR(VLOOKUP(A9,'マスタ'!$A:$F,2,FALSE),"")) | C9: =IF(A9="","",IFERROR(VLOOKUP(A9,'マスタ'!$A:$F,3,FALSE),"")) | I9: =IF(A9="",0,IFERROR(VLOOKUP(A9,'マスタ'!$A:$F,4,FALSE),0)) | J9: =IF(A9="",0,IFERROR(VLOOKUP(A9,'マスタ'!$A:$F,5,FALSE),0)) | K9: =IF(A9="",0,ROUND(I9/160*1.25*H9,0)) | L9: =IF(A9="",0,IFERROR(VLOOKUP(A9,'マスタ'!$A:$F,6,FALSE),0)) | N9: =SUM(I9:M9) | U9: =SUM(O9:T9) | V9: =N9-U9
B10: =IF(A10="","",IFERROR(VLOOKUP(A10,'マスタ'!$A:$F,2,FALSE),"")) | C10: =IF(A10="","",IFERROR(VLOOKUP(A10,'マスタ'!$A:$F,3,FALSE),"")) | I10: =IF(A10="",0,IFERROR(VLOOKUP(A10,'マスタ'!$A:$F,4,FALSE),0)) | J10: =IF(A10="",0,IFERROR(VLOOKUP(A10,'マスタ'!$A:$F,5,FALSE),0)) | K10: =IF(A10="",0,ROUND(I10/160*1.25*H10,0)) | L10: =IF(A10="",0,IFERROR(VLOOKUP(A10,'マスタ'!$A:$F,6,FALSE),0)) | N10: =SUM(I10:M10) | U10: =SUM(O10:T10) | V10: =N10-U10
B11: =IF(A11="","",IFERROR(VLOOKUP(A11,'マスタ'!$A:$F,2,FALSE),"")) | C11: =IF(A11="","",IFERROR(VLOOKUP(A11,'マスタ'!$A:$F,3,FALSE),"")) | I11: =IF(A11="",0,IFERROR(VLOOKUP(A11,'マスタ'!$A:$F,4,FALSE),0)) | J11: =IF(A11="",0,IFERROR(VLOOKUP(A11,'マスタ'!$A:$F,5,FALSE),0)) | K11: =IF(A11="",0,ROUND(I11/160*1.25*H11,0)) | L11: =IF(A11="",0,IFERROR(VLOOKUP(A11,'マスタ'!$A:$F,6,FALSE),0)) | N11: =SUM(I11:M11) | U11: =SUM(O11:T11) | V11: =N11-U11
B12: =IF(A12="","",IFERROR(VLOOKUP(A12,'マスタ'!$A:$F,2,FALSE),"")) | C12: =IF(A12="","",IFERROR(VLOOKUP(A12,'マスタ'!$A:$F,3,FALSE),"")) | I12: =IF(A12="",0,IFERROR(VLOOKUP(A12,'マスタ'!$A:$F,4,FALSE),0)) | J12: =IF(A12="",0,IFERROR(VLOOKUP(A12,'マスタ'!$A:$F,5,FALSE),0)) | K12: =IF(A12="",0,ROUND(I12/160*1.25*H12,0)) | L12: =IF(A12="",0,IFERROR(VLOOKUP(A12,'マスタ'!$A:$F,6,FALSE),0)) | N12: =SUM(I12:M12) | U12: =SUM(O12:T12) | V12: =N12-U12
B13: =IF(A13="","",IFERROR(VLOOKUP(A13,'マスタ'!$A:$F,2,FALSE),"")) | C13: =IF(A13="","",IFERROR(VLOOKUP(A13,'マスタ'!$A:$F,3,FALSE),"")) | I13: =IF(A13="",0,IFERROR(VLOOKUP(A13,'マスタ'!$A:$F,4,FALSE),0)) | J13: =IF(A13="",0,IFERROR(VLOOKUP(A13,'マスタ'!$A:$F,5,FALSE),0)) | K13: =IF(A13="",0,ROUND(I13/160*1.25*H13,0)) | L13: =IF(A13="",0,IFERROR(VLOOKUP(A13,'マスタ'!$A:$F,6,FALSE),0)) | N13: =SUM(I13:M13) | U13: =SUM(O13:T13) | V13: =N13-U13
B14: =IF(A14="","",IFERROR(VLOOKUP(A14,'マスタ'!$A:$F,2,FALSE),"")) | C14: =IF(A14="","",IFERROR(VLOOKUP(A14,'マスタ'!$A:$F,3,FALSE),"")) | I14: =IF(A14="",0,IFERROR(VLOOKUP(A14,'マスタ'!$A:$F,4,FALSE),0)) | J14: =IF(A14="",0,IFERROR(VLOOKUP(A14,'マスタ'!$A:$F,5,FALSE),0)) | K14: =IF(A14="",0,ROUND(I14/160*1.25*H14,0)) | L14: =IF(A14="",0,IFERROR(VLOOKUP(A14,'マスタ'!$A:$F,6,FALSE),0)) | N14: =SUM(I14:M14) | U14: =SUM(O14:T14) | V14: =N14-U14
A15: 合 計 | D15: =SUM(D5:D14) | E15: =SUM(E5:E14) | F15: =SUM(F5:F14) | G15: =SUM(G5:G14) | H15: =SUM(H5:H14) | I15: =SUM(I5:I14) | J15: =SUM(J5:J14) | K15: =SUM(K5:K14) | ... V15: =SUM(V5:V14)

Sheet 2月
A1: 給与台帳 2月分
A2: 会社名：株式会社サンプル | L2: 作成日：2026年2月
A3: 基本情報 | D3: 勤 怠 情 報 | I3: 支 給 項 目 | O3: 控 除 項 目 | V3: 差引 支給額
A4: 従業員 番号 | B4: 氏名 | C4: 所属 | D4: 所定 労働日数 | E4: 出勤 日数 | F4: 欠勤 日数 | G4: 有給 取得日数 | H4: 残業 時間 | I4: 基本給 | J4: 役職 手当 | K4: 残業 手当 | L4: 通勤 手当 | M4: その他 手当 | N4: 支給 合計 | O4: 健康 保険 | P4: 厚生 年金 | Q4: 雇用 保険 | R4: 所得税 | S4: 住民税 | T4: その他 控除 | U4: 控除 合計 | V4: 差引 支給額
A5: 001 | B5: =IF(A5="","",IFERROR(VLOOKUP(A5,'マスタ'!$A:$F,2,FALSE),"")) | C5: =IF(A5="","",IFERROR(VLOOKUP(A5,'マスタ'!$A:$F,3,FALSE),"")) | D5: 20 | E5: 20 | F5: 0 | G5: 0 | H5: 10 | I5: =IF(A5="",0,IFERROR(VLOOKUP(A5,'マスタ'!$A:$F,4,FALSE),0)) | J5: =IF(A5="",0,IFERROR(VLOOKUP(A5,'マスタ'!$A:$F,5,FALSE),0)) | K5: =IF(A5="",0,ROUND(I5/160*1.25*H5,0)) | L5: =IF(A5="",0,IFERROR(VLOOKUP(A5,'マスタ'!$A:$F,6,FALSE),0)) | M5: 0 | N5: =SUM(I5:M5) | O5: 17500 | P5: 32490 | Q5: 2100 | R5: 8500 | S5: 12000 | T5: 0 | U5: =SUM(O5:T5) | V5: =N5-U5
A6: 002 | B6: =IF(A6="","",IFERROR(VLOOKUP(A6,'マスタ'!$A:$F,2,FALSE),"")) | C6: =IF(A6="","",IFERROR(VLOOKUP(A6,'マスタ'!$A:$F,3,FALSE),"")) | D6: 20 | E6: 19 | F6: 1 | G6: 1 | H6: 5 | I6: =IF(A6="",0,IFERROR(VLOOKUP(A6,'マスタ'!$A:$F,4,FALSE),0)) | J6: =IF(A6="",0,IFERROR(VLOOKUP(A6,'マスタ'!$A:$F,5,FALSE),0)) | K6: =IF(A6="",0,ROUND(I6/160*1.25*H6,0)) | L6: =IF(A6="",0,IFERROR(VLOOKUP(A6,'マスタ'!$A:$F,6,FALSE),0)) | M6: 0 | N6: =SUM(I6:M6) | O6: 14000 | P6: 25990 | Q6: 1680 | R6: 5500 | S6: 9000 | T6: 0 | U6: =SUM(O6:T6) | V6: =N6-U6
A7: 003 | B7: =IF(A7="","",IFERROR(VLOOKUP(A7,'マスタ'!$A:$F,2,FALSE),"")) | C7: =IF(A7="","",IFERROR(VLOOKUP(A7,'マスタ'!$A:$F,3,FALSE),"")) | D7: 20 | E7: 20 | F7: 0 | G7: 2 | H7: 15 | I7: =IF(A7="",0,IFERROR(VLOOKUP(A7,'マスタ'!$A:$F,4,FALSE),0)) | J7: =IF(A7="",0,IFERROR(VLOOKUP(A7,'マスタ'!$A:$F,5,FALSE),0)) | K7: =IF(A7="",0,ROUND(I7/160*1.25*H7,0)) | L7: =IF(A7="",0,IFERROR(VLOOKUP(A7,'マスタ'!$A:$F,6,FALSE),0)) | M7: 0 | N7: =SUM(I7:M7) | O7: 16000 | P7: 29730 | Q7: 1920 | R7: 7000 | S7: 10500 | T7: 0 | U7: =SUM(O7:T7) | V7: =N7-U7
B8: =IF(A8="","",IFERROR(VLOOKUP(A8,'マスタ'!$A:$F,2,FALSE),"")) | C8: =IF(A8="","",IFERROR(VLOOKUP(A8,'マスタ'!$A:$F,3,FALSE),"")) | I8: =IF(A8="",0,IFERROR(VLOOKUP(A8,'マスタ'!$A:$F,4,FALSE),0)) | J8: =IF(A8="",0,IFERROR(VLOOKUP(A8,'マスタ'!$A:$F,5,FALSE),0)) | K8: =IF(A8="",0,ROUND(I8/160*1.25*H8,0)) | L8: =IF(A8="",0,IFERROR(VLOOKUP(A8,'マスタ'!$A:$F,6,FALSE),0)) | N8: =SUM(I8:M8) | U8: =SUM(O8:T8) | V8: =N8-U8
B9: =IF(A9="","",IFERROR(VLOOKUP(A9,'マスタ'!$A:$F,2,FALSE),"")) | C9: =IF(A9="","",IFERROR(VLOOKUP(A9,'マスタ'!$A:$F,3,FALSE),"")) | I9: =IF(A9="",0,IFERROR(VLOOKUP(A9,'マスタ'!$A:$F,4,FALSE),0)) | J9: =IF(A9="",0,IFERROR(VLOOKUP(A9,'マスタ'!$A:$F,5,FALSE),0)) | K9: =IF(A9="",0,ROUND(I9/160*1.25*H9,0)) | L9: =IF(A9="",0,IFERROR(VLOOKUP(A9,'マスタ'!$A:$F,6,FALSE),0)) | N9: =SUM(I9:M9) | U9: =SUM(O9:T9) | V9: =N9-U9
B10: =IF(A10="","",IFERROR(VLOOKUP(A10,'マスタ'!$A:$F,2,FALSE),"")) | C10: =IF(A10="","",IFERROR(VLOOKUP(A10,'マスタ'!$A:$F,3,FALSE),"")) | I10: =IF(A10="",0,IFERROR(VLOOKUP(A10,'マスタ'!$A:$F,4,FALSE),0)) | J10: =IF(A10="",0,IFERROR(VLOOKUP(A10,'マスタ'!$A:$F,5,FALSE),0)) | K10: =IF(A10="",0,ROUND(I10/160*1.25*H10,0)) | L10: =IF(A10="",0,IFERROR(VLOOKUP(A10,'マスタ'!$A:$F,6,FALSE),0)) | N10: =SUM(I10:M10) | U10: =SUM(O10:T10) | V10: =N10-U10
B11: =IF(A11="","",IFERROR(VLOOKUP(A11,'マスタ'!$A:$F,2,FALSE),"")) | C11: =IF(A11="","",IFERROR(VLOOKUP(A11,'マスタ'!$A:$F,3,FALSE),"")) | I11: =IF(A11="",0,IFERROR(VLOOKUP(A11,'マスタ'!$A:$F,4,FALSE),0)) | J11: =IF(A11="",0,IFERROR(VLOOKUP(A11,'マスタ'!$A:$F,5,FALSE),0)) | K11: =IF(A11="",0,ROUND(I11/160*1.25*H11,0)) | L11: =IF(A11="",0,IFERROR(VLOOKUP(A11,'マスタ'!$A:$F,6,FALSE),0)) | N11: =SUM(I11:M11) | U11: =SUM(O11:T11) | V11: =N11-U11
B12: =IF(A12="","",IFERROR(VLOOKUP(A12,'マスタ'!$A:$F,2,FALSE),"")) | C12: =IF(A12="","",IFERROR(VLOOKUP(A12,'マスタ'!$A:$F,3,FALSE),"")) | I12: =IF(A12="",0,IFERROR(VLOOKUP(A12,'マスタ'!$A:$F,4,FALSE),0)) | J12: =IF(A12="",0,IFERROR(VLOOKUP(A12,'マスタ'!$A:$F,5,FALSE),0)) | K12: =IF(A12="",0,ROUND(I12/160*1.25*H12,0)) | L12: =IF(A12="",0,IFERROR(VLOOKUP(A12,'マスタ'!$A:$F,6,FALSE),0)) | N12: =SUM(I12:M12) | U12: =SUM(O12:T12) | V12: =N12-U12
B13: =IF(A13="","",IFERROR(VLOOKUP(A13,'マスタ'!$A:$F,2,FALSE),"")) | C13: =IF(A13="","",IFERROR(VLOOKUP(A13,'マスタ'!$A:$F,3,FALSE),"")) | I13: =IF(A13="",0,IFERROR(VLOOKUP(A13,'マスタ'!$A:$F,4,FALSE),0)) | J13: =IF(A13="",0,IFERROR(VLOOKUP(A13,'マスタ'!$A:$F,5,FALSE),0)) | K13: =IF(A13="",0,ROUND(I13/160*1.25*H13,0)) | L13: =IF(A13="",0,IFERROR(VLOOKUP(A13,'マスタ'!$A:$F,6,FALSE),0)) | N13: =SUM(I13:M13) | U13: =SUM(O13:T13) | V13: =N13-U13
B14: =IF(A14="","",IFERROR(VLOOKUP(A14,'マスタ'!$A:$F,2,FALSE),"")) | C14: =IF(A14="","",IFERROR(VLOOKUP(A14,'マスタ'!$A:$F,3,FALSE),"")) | I14: =IF(A14="",0,IFERROR(VLOOKUP(A14,'マスタ'!$A:$F,4,FALSE),0)) | J14: =IF(A14="",0,IFERROR(VLOOKUP(A14,'マスタ'!$A:$F,5,FALSE),0)) | K14: =IF(A14="",0,ROUND(I14/160*1.25*H14,0)) | L14: =IF(A14="",0,IFERROR(VLOOKUP(A14,'マスタ'!$A:$F,6,FALSE),0)) | N14: =SUM(I14:M14) | U14: =SUM(O14:T14) | V14: =N14-U14
A15: 合 計 | D15: =SUM(D5:D14) | E15: =SUM(E5:E14) | F15: =SUM(F5:F14) | G15: =SUM(G5:G14) | H15: =SUM(H5:H14) | I15: =SUM(I5:I14) | J15: =SUM(J5:J14) | K15: =SUM(K5:K14) | ... V15: =SUM(V5:V14)

Sheet 3月
A1: 給与台帳 3月分
A2: 会社名：株式会社サンプル | L2: 作成日：2026年3月
A3: 基本情報 | D3: 勤 怠 情 報 | I3: 支 給 項 目 | O3: 控 除 項 目 | V3: 差引 支給額
A4: 従業員 番号 | B4: 氏名 | C4: 所属 | D4: 所定 労働日数 | E4: 出勤 日数 | F4: 欠勤 日数 | G4: 有給 取得日数 | H4: 残業 時間 | I4: 基本給 | J4: 役職 手当 | K4: 残業 手当 | L4: 通勤 手当 | M4: その他 手当 | N4: 支給 合計 | O4: 健康 保険 | P4: 厚生 年金 | Q4: 雇用 保険 | R4: 所得税 | S4: 住民税 | T4: その他 控除 | U4: 控除 合計 | V4: 差引 支給額
A5: 001 | B5: =IF(A5="","",IFERROR(VLOOKUP(A5,'マスタ'!$A:$F,2,FALSE),"")) | C5: =IF(A5="","",IFERROR(VLOOKUP(A5,'マスタ'!$A:$F,3,FALSE),"")) | D5: 20 | E5: 20 | F5: 0 | G5: 0 | H5: 10 | I5: =IF(A5="",0,IFERROR(VLOOKUP(A5,'マスタ'!$A:$F,4,FALSE),0)) | J5: =IF(A5="",0,IFERROR(VLOOKUP(A5,'マスタ'!$A:$F,5,FALSE),0)) | K5: =IF(A5="",0,ROUND(I5/160*1.25*H5,0)) | L5: =IF(A5="",0,IFERROR(VLOOKUP(A5,'マスタ'!$A:$F,6,FALSE),0)) | M5: 0 | N5: =SUM(I5:M5) | O5: 17500 | P5: 32490 | Q5: 2100 | R5: 8500 | S5: 12000 | T5: 0 | U5: =SUM(O5:T5) | V5: =N5-U5
A6: 002 | B6: =IF(A6="","",IFERROR(VLOOKUP(A6,'マスタ'!$A:$F,2,FALSE),"")) | C6: =IF(A6="","",IFERROR(VLOOKUP(A6,'マスタ'!$A:$F,3,FALSE),"")) | D6: 20 | E6: 19 | F6: 1 | G6: 1 | H6: 5 | I6: =IF(A6="",0,IFERROR(VLOOKUP(A6,'マスタ'!$A:$F,4,FALSE),0)) | J6: =IF(A6="",0,IFERROR(VLOOKUP(A6,'マスタ'!$A:$F,5,FALSE),0)) | K6: =IF(A6="",0,ROUND(I6/160*1.25*H6,0)) | L6: =IF(A6="",0,IFERROR(VLOOKUP(A6,'マスタ'!$A:$F,6,FALSE),0)) | M6: 0 | N6: =SUM(I6:M6) | O6: 14000 | P6: 25990 | Q6: 1680 | R6: 5500 | S6: 9000 | T6: 0 | U6: =SUM(O6:T6) | V6: =N6-U6
A7: 003 | B7: =IF(A7="","",IFERROR(VLOOKUP(A7,'マスタ'!$A:$F,2,FALSE),"")) | C7: =IF(A7="","",IFERROR(VLOOKUP(A7,'マスタ'!$A:$F,3,FALSE),"")) | D7: 20 | E7: 20 | F7: 0 | G7: 2 | H7: 15 | I7: =IF(A7="",0,IFERROR(VLOOKUP(A7,'マスタ'!$A:$F,4,FALSE),0)) | J7: =IF(A7="",0,IFERROR(VLOOKUP(A7,'マスタ'!$A:$F,5,FALSE),0)) | K7: =IF(A7="",0,ROUND(I7/160*1.25*H7,0)) | L7: =IF(A7="",0,IFERROR(VLOOKUP(A7,'マスタ'!$A:$F,6,FALSE),0)) | M7: 0 | N7: =SUM(I7:M7) | O7: 16000 | P7: 29730 | Q7: 1920 | R7: 7000 | S7: 10500 | T7: 0 | U7: =SUM(O7:T7) | V7: =N7-U7
B8: =IF(A8="","",IFERROR(VLOOKUP(A8,'マスタ'!$A:$F,2,FALSE),"")) | C8: =IF(A8="","",IFERROR(VLOOKUP(A8,'マスタ'!$A:$F,3,FALSE),"")) | I8: =IF(A8="",0,IFERROR(VLOOKUP(A8,'マスタ'!$A:$F,4,FALSE),0)) | J8: =IF(A8="",0,IFERROR(VLOOKUP(A8,'マスタ'!$A:$F,5,FALSE),0)) | K8: =IF(A8="",0,ROUND(I8/160*1.25*H8,0)) | L8: =IF(A8="",0,IFERROR(VLOOKUP(A8,'マスタ'!$A:$F,6,FALSE),0)) | N8: =SUM(I8:M8) | U8: =SUM(O8:T8) | V8: =N8-U8
B9: =IF(A9="","",IFERROR(VLOOKUP(A9,'マスタ'!$A:$F,2,FALSE),"")) | C9: =IF(A9="","",IFERROR(VLOOKUP(A9,'マスタ'!$A:$F,3,FALSE),"")) | I9: =IF(A9="",0,IFERROR(VLOOKUP(A9,'マスタ'!$A:$F,4,FALSE),0)) | J9: =IF(A9="",0,IFERROR(VLOOKUP(A9,'マスタ'!$A:$F,5,FALSE),0)) | K9: =IF(A9="",0,ROUND(I9/160*1.25*H9,0)) | L9: =IF(A9="",0,IFERROR(VLOOKUP(A9,'マスタ'!$A:$F,6,FALSE),0)) | N9: =SUM(I9:M9) | U9: =SUM(O9:T9) | V9: =N9-U9
B10: =IF(A10="","",IFERROR(VLOOKUP(A10,'マスタ'!$A:$F,2,FALSE),"")) | C10: =IF(A10="","",IFERROR(VLOOKUP(A10,'マスタ'!$A:$F,3,FALSE),"")) | I10: =IF(A10="",0,IFERROR(VLOOKUP(A10,'マスタ'!$A:$F,4,FALSE),0)) | J10: =IF(A10="",0,IFERROR(VLOOKUP(A10,'マスタ'!$A:$F,5,FALSE),0)) | K10: =IF(A10="",0,ROUND(I10/160*1.25*H10,0)) | L10: =IF(A10="",0,IFERROR(VLOOKUP(A10,'マスタ'!$A:$F,6,FALSE),0)) | N10: =SUM(I10:M10) | U10: =SUM(O10:T10) | V10: =N10-U10
B11: =IF(A11="","",IFERROR(VLOOKUP(A11,'マスタ'!$A:$F,2,FALSE),"")) | C11: =IF(A11="","",IFERROR(VLOOKUP(A11,'マスタ'!$A:$F,3,FALSE),"")) | I11: =IF(A11="",0,IFERROR(VLOOKUP(A11,'マスタ'!$A:$F,4,FALSE),0)) | J11: =IF(A11="",0,IFERROR(VLOOKUP(A11,'マスタ'!$A:$F,5,FALSE),0)) | K11: =IF(A11="",0,ROUND(I11/160*1.25*H11,0)) | L11: =IF(A11="",0,IFERROR(VLOOKUP(A11,'マスタ'!$A:$F,6,FALSE),0)) | N11: =SUM(I11:M11) | U11: =SUM(O11:T11) | V11: =N11-U11
B12: =IF(A12="","",IFERROR(VLOOKUP(A12,'マスタ'!$A:$F,2,FALSE),"")) | C12: =IF(A12="","",IFERROR(VLOOKUP(A12,'マスタ'!$A:$F,3,FALSE),"")) | I12: =IF(A12="",0,IFERROR(VLOOKUP(A12,'マスタ'!$A:$F,4,FALSE),0)) | J12: =IF(A12="",0,IFERROR(VLOOKUP(A12,'マスタ'!$A:$F,5,FALSE),0)) | K12: =IF(A12="",0,ROUND(I12/160*1.25*H12,0)) | L12: =IF(A12="",0,IFERROR(VLOOKUP(A12,'マスタ'!$A:$F,6,FALSE),0)) | N12: =SUM(I12:M12) | U12: =SUM(O12:T12) | V12: =N12-U12
B13: =IF(A13="","",IFERROR(VLOOKUP(A13,'マスタ'!$A:$F,2,FALSE),"")) | C13: =IF(A13="","",IFERROR(VLOOKUP(A13,'マスタ'!$A:$F,3,FALSE),"")) | I13: =IF(A13="",0,IFERROR(VLOOKUP(A13,'マスタ'!$A:$F,4,FALSE),0)) | J13: =IF(A13="",0,IFERROR(VLOOKUP(A13,'マスタ'!$A:$F,5,FALSE),0)) | K13: =IF(A13="",0,ROUND(I13/160*1.25*H13,0)) | L13: =IF(A13="",0,IFERROR(VLOOKUP(A13,'マスタ'!$A:$F,6,FALSE),0)) | N13: =SUM(I13:M13) | U13: =SUM(O13:T13) | V13: =N13-U13
B14: =IF(A14="","",IFERROR(VLOOKUP(A14,'マスタ'!$A:$F,2,FALSE),"")) | C14: =IF(A14="","",IFERROR(VLOOKUP(A14,'マスタ'!$A:$F,3,FALSE),"")) | I14: =IF(A14="",0,IFERROR(VLOOKUP(A14,'マスタ'!$A:$F,4,FALSE),0)) | J14: =IF(A14="",0,IFERROR(VLOOKUP(A14,'マスタ'!$A:$F,5,FALSE),0)) | K14: =IF(A14="",0,ROUND(I14/160*1.25*H14,0)) | L14: =IF(A14="",0,IFERROR(VLOOKUP(A14,'マスタ'!$A:$F,6,FALSE),0)) | N14: =SUM(I14:M14) | U14: =SUM(O14:T14) | V14: =N14-U14
A15: 合 計 | D15: =SUM(D5:D14) | E15: =SUM(E5:E14) | F15: =SUM(F5:F14) | G15: =SUM(G5:G14) | H15: =SUM(H5:H14) | I15: =SUM(I5:I14) | J15: =SUM(J5:J14) | K15: =SUM(K5:K14) | ... V15: =SUM(V5:V14)

Sheet 4月
A1: 給与台帳 4月分
A2: 会社名：株式会社サンプル | L2: 作成日：2026年4月
A3: 基本情報 | D3: 勤 怠 情 報 | I3: 支 給 項 目 | O3: 控 除 項 目 | V3: 差引 支給額
A4: 従業員 番号 | B4: 氏名 | C4: 所属 | D4: 所定 労働日数 | E4: 出勤 日数 | F4: 欠勤 日数 | G4: 有給 取得日数 | H4: 残業 時間 | I4: 基本給 | J4: 役職 手当 | K4: 残業 手当 | L4: 通勤 手当 | M4: その他 手当 | N4: 支給 合計 | O4: 健康 保険 | P4: 厚生 年金 | Q4: 雇用 保険 | R4: 所得税 | S4: 住民税 | T4: その他 控除 | U4: 控除 合計 | V4: 差引 支給額
A5: 001 | B5: =IF(A5="","",IFERROR(VLOOKUP(A5,'マスタ'!$A:$F,2,FALSE),"")) | C5: =IF(A5="","",IFERROR(VLOOKUP(A5,'マスタ'!$A:$F,3,FALSE),"")) | D5: 20 | E5: 20 | F5: 0 | G5: 0 | H5: 10 | I5: =IF(A5="",0,IFERROR(VLOOKUP(A5,'マスタ'!$A:$F,4,FALSE),0)) | J5: =IF(A5="",0,IFERROR(VLOOKUP(A5,'マスタ'!$A:$F,5,FALSE),0)) | K5: =IF(A5="",0,ROUND(I5/160*1.25*H5,0)) | L5: =IF(A5="",0,IFERROR(VLOOKUP(A5,'マスタ'!$A:$F,6,FALSE),0)) | M5: 0 | N5: =SUM(I5:M5) | O5: 17500 | P5: 32490 | Q5: 2100 | R5: 8500 | S5: 12000 | T5: 0 | U5: =SUM(O5:T5) | V5: =N5-U5
A6: 002 | B6: =IF(A6="","",IFERROR(VLOOKUP(A6,'マスタ'!$A:$F,2,FALSE),"")) | C6: =IF(A6="","",IFERROR(VLOOKUP(A6,'マスタ'!$A:$F,3,FALSE),"")) | D6: 20 | E6: 19 | F6: 1 | G6: 1 | H6: 5 | I6: =IF(A6="",0,IFERROR(VLOOKUP(A6,'マスタ'!$A:$F,4,FALSE),0)) | J6: =IF(A6="",0,IFERROR(VLOOKUP(A6,'マスタ'!$A:$F,5,FALSE),0)) | K6: =IF(A6="",0,ROUND(I6/160*1.25*H6,0)) | L6: =IF(A6="",0,IFERROR(VLOOKUP(A6,'マスタ'!$A:$F,6,FALSE),0)) | M6: 0 | N6: =SUM(I6:M6) | O6: 14000 | P6: 25990 | Q6: 1680 | R6: 5500 | S6: 9000 | T6: 0 | U6: =SUM(O6:T6) | V6: =N6-U6
A7: 003 | B7: =IF(A7="","",IFERROR(VLOOKUP(A7,'マスタ'!$A:$F,2,FALSE),"")) | C7: =IF(A7="","",IFERROR(VLOOKUP(A7,'マスタ'!$A:$F,3,FALSE),"")) | D7: 20 | E7: 20 | F7: 0 | G7: 2 | H7: 15 | I7: =IF(A7="",0,IFERROR(VLOOKUP(A7,'マスタ'!$A:$F,4,FALSE),0)) | J7: =IF(A7="",0,IFERROR(VLOOKUP(A7,'マスタ'!$A:$F,5,FALSE),0)) | K7: =IF(A7="",0,ROUND(I7/160*1.25*H7,0)) | L7: =IF(A7="",0,IFERROR(VLOOKUP(A7,'マスタ'!$A:$F,6,FALSE),0)) | M7: 0 | N7: =SUM(I7:M7) | O7: 16000 | P7: 29730 | Q7: 1920 | R7: 7000 | S7: 10500 | T7: 0 | U7: =SUM(O7:T7) | V7: =N7-U7
B8: =IF(A8="","",IFERROR(VLOOKUP(A8,'マスタ'!$A:$F,2,FALSE),"")) | C8: =IF(A8="","",IFERROR(VLOOKUP(A8,'マスタ'!$A:$F,3,FALSE),"")) | I8: =IF(A8="",0,IFERROR(VLOOKUP(A8,'マスタ'!$A:$F,4,FALSE),0)) | J8: =IF(A8="",0,IFERROR(VLOOKUP(A8,'マスタ'!$A:$F,5,FALSE),0)) | K8: =IF(A8="",0,ROUND(I8/160*1.25*H8,0)) | L8: =IF(A8="",0,IFERROR(VLOOKUP(A8,'マスタ'!$A:$F,6,FALSE),0)) | N8: =SUM(I8:M8) | U8: =SUM(O8:T8) | V8: =N8-U8
B9: =IF(A9="","",IFERROR(VLOOKUP(A9,'マスタ'!$A:$F,2,FALSE),"")) | C9: =IF(A9="","",IFERROR(VLOOKUP(A9,'マスタ'!$A:$F,3,FALSE),"")) | I9: =IF(A9="",0,IFERROR(VLOOKUP(A9,'マスタ'!$A:$F,4,FALSE),0)) | J9: =IF(A9="",0,IFERROR(VLOOKUP(A9,'マスタ'!$A:$F,5,FALSE),0)) | K9: =IF(A9="",0,ROUND(I9/160*1.25*H9,0)) | L9: =IF(A9="",0,IFERROR(VLOOKUP(A9,'マスタ'!$A:$F,6,FALSE),0)) | N9: =SUM(I9:M9) | U9: =SUM(O9:T9) | V9: =N9-U9
B10: =IF(A10="","",IFERROR(VLOOKUP(A10,'マスタ'!$A:$F,2,FALSE),"")) | C10: =IF(A10="","",IFERROR(VLOOKUP(A10,'マスタ'!$A:$F,3,FALSE),"")) | I10: =IF(A10="",0,IFERROR(VLOOKUP(A10,'マスタ'!$A:$F,4,FALSE),0)) | J10: =IF(A10="",0,IFERROR(VLOOKUP(A10,'マスタ'!$A:$F,5,FALSE),0)) | K10: =IF(A10="",0,ROUND(I10/160*1.25*H10,0)) | L10: =IF(A10="",0,IFERROR(VLOOKUP(A10,'マスタ'!$A:$F,6,FALSE),0)) | N10: =SUM(I10:M10) | U10: =SUM(O10:T10) | V10: =N10-U10
B11: =IF(A11="","",IFERROR(VLOOKUP(A11,'マスタ'!$A:$F,2,FALSE),"")) | C11: =IF(A11="","",IFERROR(VLOOKUP(A11,'マスタ'!$A:$F,3,FALSE),"")) | I11: =IF(A11="",0,IFERROR(VLOOKUP(A11,'マスタ'!$A:$F,4,FALSE),0)) | J11: =IF(A11="",0,IFERROR(VLOOKUP(A11,'マスタ'!$A:$F,5,FALSE),0)) | K11: =IF(A11="",0,ROUND(I11/160*1.25*H11,0)) | L11: =IF(A11="",0,IFERROR(VLOOKUP(A11,'マスタ'!$A:$F,6,FALSE),0)) | N11: =SUM(I11:M11) | U11: =SUM(O11:T11) | V11: =N11-U11
B12: =IF(A12="","",IFERROR(VLOOKUP(A12,'マスタ'!$A:$F,2,FALSE),"")) | C12: =IF(A12="","",IFERROR(VLOOKUP(A12,'マスタ'!$A:$F,3,FALSE),"")) | I12: =IF(A12="",0,IFERROR(VLOOKUP(A12,'マスタ'!$A:$F,4,FALSE),0)) | J12: =IF(A12="",0,IFERROR(VLOOKUP(A12,'マスタ'!$A:$F,5,FALSE),0)) | K12: =IF(A12="",0,ROUND(I12/160*1.25*H12,0)) | L12: =IF(A12="",0,IFERROR(VLOOKUP(A12,'マスタ'!$A:$F,6,FALSE),0)) | N12: =SUM(I12:M12) | U12: =SUM(O12:T12) | V12: =N12-U12
B13: =IF(A13="","",IFERROR(VLOOKUP(A13,'マスタ'!$A:$F,2,FALSE),"")) | C13: =IF(A13="","",IFERROR(VLOOKUP(A13,'マスタ'!$A:$F,3,FALSE),"")) | I13: =IF(A13="",0,IFERROR(VLOOKUP(A13,'マスタ'!$A:$F,4,FALSE),0)) | J13: =IF(A13="",0,IFERROR(VLOOKUP(A13,'マスタ'!$A:$F,5,FALSE),0)) | K13: =IF(A13="",0,ROUND(I13/160*1.25*H13,0)) | L13: =IF(A13="",0,IFERROR(VLOOKUP(A13,'マスタ'!$A:$F,6,FALSE),0)) | N13: =SUM(I13:M13) | U13: =SUM(O13:T13) | V13: =N13-U13
B14: =IF(A14="","",IFERROR(VLOOKUP(A14,'マスタ'!$A:$F,2,FALSE),"")) | C14: =IF(A14="","",IFERROR(VLOOKUP(A14,'マスタ'!$A:$F,3,FALSE),"")) | I14: =IF(A14="",0,IFERROR(VLOOKUP(A14,'マスタ'!$A:$F,4,FALSE),0)) | J14: =IF(A14="",0,IFERROR(VLOOKUP(A14,'マスタ'!$A:$F,5,FALSE),0)) | K14: =IF(A14="",0,ROUND(I14/160*1.25*H14,0)) | L14: =IF(A14="",0,IFERROR(VLOOKUP(A14,'マスタ'!$A:$F,6,FALSE),0)) | N14: =SUM(I14:M14) | U14: =SUM(O14:T14) | V14: =N14-U14
A15: 合 計 | D15: =SUM(D5:D14) | E15: =SUM(E5:E14) | F15: =SUM(F5:F14) | G15: =SUM(G5:G14) | H15: =SUM(H5:H14) | I15: =SUM(I5:I14) | J15: =SUM(J5:J14) | K15: =SUM(K5:K14) | ... V15: =SUM(V5:V14)

Sheet 5月
A1: 給与台帳 5月分
A2: 会社名：株式会社サンプル | L2: 作成日：2026年5月
A3: 基本情報 | D3: 勤 怠 情 報 | I3: 支 給 項 目 | O3: 控 除 項 目 | V3: 差引 支給額
A4: 従業員 番号 | B4: 氏名 | C4: 所属 | D4: 所定 労働日数 | E4: 出勤 日数 | F4: 欠勤 日数 | G4: 有給 取得日数 | H4: 残業 時間 | I4: 基本給 | J4: 役職 手当 | K4: 残業 手当 | L4: 通勤 手当 | M4: その他 手当 | N4: 支給 合計 | O4: 健康 保険 | P4: 厚生 年金 | Q4: 雇用 保険 | R4: 所得税 | S4: 住民税 | T4: その他 控除 | U4: 控除 合計 | V4: 差引 支給額
A5: 001 | B5: =IF(A5="","",IFERROR(VLOOKUP(A5,'マスタ'!$A:$F,2,FALSE),"")) | C5: =IF(A5="","",IFERROR(VLOOKUP(A5,'マスタ'!$A:$F,3,FALSE),"")) | D5: 20 | E5: 20 | F5: 0 | G5: 0 | H5: 10 | I5: =IF(A5="",0,IFERROR(VLOOKUP(A5,'マスタ'!$A:$F,4,FALSE),0)) | J5: =IF(A5="",0,IFERROR(VLOOKUP(A5,'マスタ'!$A:$F,5,FALSE),0)) | K5: =IF(A5="",0,ROUND(I5/160*1.25*H5,0)) | L5: =IF(A5="",0,IFERROR(VLOOKUP(A5,'マスタ'!$A:$F,6,FALSE),0)) | M5: 0 | N5: =SUM(I5:M5) | O5: 17500 | P5: 32490 | Q5: 2100 | R5: 8500 | S5: 12000 | T5: 0 | U5: =SUM(O5:T5) | V5: =N5-U5
A6: 002 | B6: =IF(A6="","",IFERROR(VLOOKUP(A6,'マスタ'!$A:$F,2,FALSE),"")) | C6: =IF(A6="","",IFERROR(VLOOKUP(A6,'マスタ'!$A:$F,3,FALSE),"")) | D6: 20 | E6: 19 | F6: 1 | G6: 1 | H6: 5 | I6: =IF(A6="",0,IFERROR(VLOOKUP(A6,'マスタ'!$A:$F,4,FALSE),0)) | J6: =IF(A6="",0,IFERROR(VLOOKUP(A6,'マスタ'!$A:$F,5,FALSE),0)) | K6: =IF(A6="",0,ROUND(I6/160*1.25*H6,0)) | L6: =IF(A6="",0,IFERROR(VLOOKUP(A6,'マスタ'!$A:$F,6,FALSE),0)) | M6: 0 | N6: =SUM(I6:M6) | O6: 14000 | P6: 25990 | Q6: 1680 | R6: 5500 | S6: 9000 | T6: 0 | U6: =SUM(O6:T6) | V6: =N6-U6
A7: 003 | B7: =IF(A7="","",IFERROR(VLOOKUP(A7,'マスタ'!$A:$F,2,FALSE),"")) | C7: =IF(A7="","",IFERROR(VLOOKUP(A7,'マスタ'!$A:$F,3,FALSE),"")) | D7: 20 | E7: 20 | F7: 0 | G7: 2 | H7: 15 | I7: =IF(A7="",0,IFERROR(VLOOKUP(A7,'マスタ'!$A:$F,4,FALSE),0)) | J7: =IF(A7="",0,IFERROR(VLOOKUP(A7,'マスタ'!$A:$F,5,FALSE),0)) | K7: =IF(A7="",0,ROUND(I7/160*1.25*H7,0)) | L7: =IF(A7="",0,IFERROR(VLOOKUP(A7,'マスタ'!$A:$F,6,FALSE),0)) | M7: 0 | N7: =SUM(I7:M7) | O7: 16000 | P7: 29730 | Q7: 1920 | R7: 7000 | S7: 10500 | T7: 0 | U7: =SUM(O7:T7) | V7: =N7-U7
B8: =IF(A8="","",IFERROR(VLOOKUP(A8,'マスタ'!$A:$F,2,FALSE),"")) | C8: =IF(A8="","",IFERROR(VLOOKUP(A8,'マスタ'!$A:$F,3,FALSE),"")) | I8: =IF(A8="",0,IFERROR(VLOOKUP(A8,'マスタ'!$A:$F,4,FALSE),0)) | J8: =IF(A8="",0,IFERROR(VLOOKUP(A8,'マスタ'!$A:$F,5,FALSE),0)) | K8: =IF(A8="",0,ROUND(I8/160*1.25*H8,0)) | L8: =IF(A8="",0,IFERROR(VLOOKUP(A8,'マスタ'!$A:$F,6,FALSE),0)) | N8: =SUM(I8:M8) | U8: =SUM(O8:T8) | V8: =N8-U8
B9: =IF(A9="","",IFERROR(VLOOKUP(A9,'マスタ'!$A:$F,2,FALSE),"")) | C9: =IF(A9="","",IFERROR(VLOOKUP(A9,'マスタ'!$A:$F,3,FALSE),"")) | I9: =IF(A9="",0,IFERROR(VLOOKUP(A9,'マスタ'!$A:$F,4,FALSE),0)) | J9: =IF(A9="",0,IFERROR(VLOOKUP(A9,'マスタ'!$A:$F,5,FALSE),0)) | K9: =IF(A9="",0,ROUND(I9/160*1.25*H9,0)) | L9: =IF(A9="",0,IFERROR(VLOOKUP(A9,'マスタ'!$A:$F,6,FALSE),0)) | N9: =SUM(I9:M9) | U9: =SUM(O9:T9) | V9: =N9-U9
B10: =IF(A10="","",IFERROR(VLOOKUP(A10,'マスタ'!$A:$F,2,FALSE),"")) | C10: =IF(A10="","",IFERROR(VLOOKUP(A10,'マスタ'!$A:$F,3,FALSE),"")) | I10: =IF(A10="",0,IFERROR(VLOOKUP(A10,'マスタ'!$A:$F,4,FALSE),0)) | J10: =IF(A10="",0,IFERROR(VLOOKUP(A10,'マスタ'!$A:$F,5,FALSE),0)) | K10: =IF(A10="",0,ROUND(I10/160*1.25*H10,0)) | L10: =IF(A10="",0,IFERROR(VLOOKUP(A10,'マスタ'!$A:$F,6,FALSE),0)) | N10: =SUM(I10:M10) | U10: =SUM(O10:T10) | V10: =N10-U10
B11: =IF(A11="","",IFERROR(VLOOKUP(A11,'マスタ'!$A:$F,2,FALSE),"")) | C11: =IF(A11="","",IFERROR(VLOOKUP(A11,'マスタ'!$A:$F,3,FALSE),"")) | I11: =IF(A11="",0,IFERROR(VLOOKUP(A11,'マスタ'!$A:$F,4,FALSE),0)) | J11: =IF(A11="",0,IFERROR(VLOOKUP(A11,'マスタ'!$A:$F,5,FALSE),0)) | K11: =IF(A11="",0,ROUND(I11/160*1.25*H11,0)) | L11: =IF(A11="",0,IFERROR(VLOOKUP(A11,'マスタ'!$A:$F,6,FALSE),0)) | N11: =SUM(I11:M11) | U11: =SUM(O11:T11) | V11: =N11-U11
B12: =IF(A12="","",IFERROR(VLOOKUP(A12,'マスタ'!$A:$F,2,FALSE),"")) | C12: =IF(A12="","",IFERROR(VLOOKUP(A12,'マスタ'!$A:$F,3,FALSE),"")) | I12: =IF(A12="",0,IFERROR(VLOOKUP(A12,'マスタ'!$A:$F,4,FALSE),0)) | J12: =IF(A12="",0,IFERROR(VLOOKUP(A12,'マスタ'!$A:$F,5,FALSE),0)) | K12: =IF(A12="",0,ROUND(I12/160*1.25*H12,0)) | L12: =IF(A12="",0,IFERROR(VLOOKUP(A12,'マスタ'!$A:$F,6,FALSE),0)) | N12: =SUM(I12:M12) | U12: =SUM(O12:T12) | V12: =N12-U12
B13: =IF(A13="","",IFERROR(VLOOKUP(A13,'マスタ'!$A:$F,2,FALSE),"")) | C13: =IF(A13="","",IFERROR(VLOOKUP(A13,'マスタ'!$A:$F,3,FALSE),"")) | I13: =IF(A13="",0,IFERROR(VLOOKUP(A13,'マスタ'!$A:$F,4,FALSE),0)) | J13: =IF(A13="",0,IFERROR(VLOOKUP(A13,'マスタ'!$A:$F,5,FALSE),0)) | K13: =IF(A13="",0,ROUND(I13/160*1.25*H13,0)) | L13: =IF(A13="",0,IFERROR(VLOOKUP(A13,'マスタ'!$A:$F,6,FALSE),0)) | N13: =SUM(I13:M13) | U13: =SUM(O13:T13) | V13: =N13-U13
B14: =IF(A14="","",IFERROR(VLOOKUP(A14,'マスタ'!$A:$F,2,FALSE),"")) | C14: =IF(A14="","",IFERROR(VLOOKUP(A14,'マスタ'!$A:$F,3,FALSE),"")) | I14: =IF(A14="",0,IFERROR(VLOOKUP(A14,'マスタ'!$A:$F,4,FALSE),0)) | J14: =IF(A14="",0,IFERROR(VLOOKUP(A14,'マスタ'!$A:$F,5,FALSE),0)) | K14: =IF(A14="",0,ROUND(I14/160*1.25*H14,0)) | L14: =IF(A14="",0,IFERROR(VLOOKUP(A14,'マスタ'!$A:$F,6,FALSE),0)) | N14: =SUM(I14:M14) | U14: =SUM(O14:T14) | V14: =N14-U14
A15: 合 計 | D15: =SUM(D5:D14) | E15: =SUM(E5:E14) | F15: =SUM(F5:F14) | G15: =SUM(G5:G14) | H15: =SUM(H5:H14) | I15: =SUM(I5:I14) | J15: =SUM(J5:J14) | K15: =SUM(K5:K14) | ... V15: =SUM(V5:V14)

Sheet 6月
A1: 給与台帳 6月分
A2: 会社名：株式会社サンプル | L2: 作成日：2026年6月
A3: 基本情報 | D3: 勤 怠 情 報 | I3: 支 給 項 目 | O3: 控 除 項 目 | V3: 差引 支給額
A4: 従業員 番号 | B4: 氏名 | C4: 所属 | D4: 所定 労働日数 | E4: 出勤 日数 | F4: 欠勤 日数 | G4: 有給 取得日数 | H4: 残業 時間 | I4: 基本給 | J4: 役職 手当 | K4: 残業 手当 | L4: 通勤 手当 | M4: その他 手当 | N4: 支給 合計 | O4: 健康 保険 | P4: 厚生 年金 | Q4: 雇用 保険 | R4: 所得税 | S4: 住民税 | T4: その他 控除 | U4: 控除 合計 | V4: 差引 支給額
A5: 001 | B5: =IF(A5="","",IFERROR(VLOOKUP(A5,'マスタ'!$A:$F,2,FALSE),"")) | C5: =IF(A5="","",IFERROR(VLOOKUP(A5,'マスタ'!$A:$F,3,FALSE),"")) | D5: 20 | E5: 20 | F5: 0 | G5: 0 | H5: 10 | I5: =IF(A5="",0,IFERROR(VLOOKUP(A5,'マスタ'!$A:$F,4,FALSE),0)) | J5: =IF(A5="",0,IFERROR(VLOOKUP(A5,'マスタ'!$A:$F,5,FALSE),0)) | K5: =IF(A5="",0,ROUND(I5/160*1.25*H5,0)) | L5: =IF(A5="",0,IFERROR(VLOOKUP(A5,'マスタ'!$A:$F,6,FALSE),0)) | M5: 0 | N5: =SUM(I5:M5) | O5: 17500 | P5: 32490 | Q5: 2100 | R5: 8500 | S5: 12000 | T5: 0 | U5: =SUM(O5:T5) | V5: =N5-U5
A6: 002 | B6: =IF(A6="","",IFERROR(VLOOKUP(A6,'マスタ'!$A:$F,2,FALSE),"")) | C6: =IF(A6="","",IFERROR(VLOOKUP(A6,'マスタ'!$A:$F,3,FALSE),"")) | D6: 20 | E6: 19 | F6: 1 | G6: 1 | H6: 5 | I6: =IF(A6="",0,IFERROR(VLOOKUP(A6,'マスタ'!$A:$F,4,FALSE),0)) | J6: =IF(A6="",0,IFERROR(VLOOKUP(A6,'マスタ'!$A:$F,5,FALSE),0)) | K6: =IF(A6="",0,ROUND(I6/160*1.25*H6,0)) | L6: =IF(A6="",0,IFERROR(VLOOKUP(A6,'マスタ'!$A:$F,6,FALSE),0)) | M6: 0 | N6: =SUM(I6:M6) | O6: 14000 | P6: 25990 | Q6: 1680 | R6: 5500 | S6: 9000 | T6: 0 | U6: =SUM(O6:T6) | V6: =N6-U6
A7: 003 | B7: =IF(A7="","",IFERROR(VLOOKUP(A7,'マスタ'!$A:$F,2,FALSE),"")) | C7: =IF(A7="","",IFERROR(VLOOKUP(A7,'マスタ'!$A:$F,3,FALSE),"")) | D7: 20 | E7: 20 | F7: 0 | G7: 2 | H7: 15 | I7: =IF(A7="",0,IFERROR(VLOOKUP(A7,'マスタ'!$A:$F,4,FALSE),0)) | J7: =IF(A7="",0,IFERROR(VLOOKUP(A7,'マスタ'!$A:$F,5,FALSE),0)) | K7: =IF(A7="",0,ROUND(I7/160*1.25*H7,0)) | L7: =IF(A7="",0,IFERROR(VLOOKUP(A7,'マスタ'!$A:$F,6,FALSE),0)) | M7: 0 | N7: =SUM(I7:M7) | O7: 16000 | P7: 29730 | Q7: 1920 | R7: 7000 | S7: 10500 | T7: 0 | U7: =SUM(O7:T7) | V7: =N7-U7
B8: =IF(A8="","",IFERROR(VLOOKUP(A8,'マスタ'!$A:$F,2,FALSE),"")) | C8: =IF(A8="","",IFERROR(VLOOKUP(A8,'マスタ'!$A:$F,3,FALSE),"")) | I8: =IF(A8="",0,IFERROR(VLOOKUP(A8,'マスタ'!$A:$F,4,FALSE),0)) | J8: =IF(A8="",0,IFERROR(VLOOKUP(A8,'マスタ'!$A:$F,5,FALSE),0)) | K8: =IF(A8="",0,ROUND(I8/160*1.25*H8,0)) | L8: =IF(A8="",0,IFERROR(VLOOKUP(A8,'マスタ'!$A:$F,6,FALSE),0)) | N8: =SUM(I8:M8) | U8: =SUM(O8:T8) | V8: =N8-U8
B9: =IF(A9="","",IFERROR(VLOOKUP(A9,'マスタ'!$A:$F,2,FALSE),"")) | C9: =IF(A9="","",IFERROR(VLOOKUP(A9,'マスタ'!$A:$F,3,FALSE),"")) | I9: =IF(A9="",0,IFERROR(VLOOKUP(A9,'マスタ'!$A:$F,4,FALSE),0)) | J9: =IF(A9="",0,IFERROR(VLOOKUP(A9,'マスタ'!$A:$F,5,FALSE),0)) | K9: =IF(A9="",0,ROUND(I9/160*1.25*H9,0)) | L9: =IF(A9="",0,IFERROR(VLOOKUP(A9,'マスタ'!$A:$F,6,FALSE),0)) | N9: =SUM(I9:M9) | U9: =SUM(O9:T9) | V9: =N9-U9
B10: =IF(A10="","",IFERROR(VLOOKUP(A10,'マスタ'!$A:$F,2,FALSE),"")) | C10: =IF(A10="","",IFERROR(VLOOKUP(A10,'マスタ'!$A:$F,3,FALSE),"")) | I10: =IF(A10="",0,IFERROR(VLOOKUP(A10,'マスタ'!$A:$F,4,FALSE),0)) | J10: =IF(A10="",0,IFERROR(VLOOKUP(A10,'マスタ'!$A:$F,5,FALSE),0)) | K10: =IF(A10="",0,ROUND(I10/160*1.25*H10,0)) | L10: =IF(A10="",0,IFERROR(VLOOKUP(A10,'マスタ'!$A:$F,6,FALSE),0)) | N10: =SUM(I10:M10) | U10: =SUM(O10:T10) | V10: =N10-U10
B11: =IF(A11="","",IFERROR(VLOOKUP(A11,'マスタ'!$A:$F,2,FALSE),"")) | C11: =IF(A11="","",IFERROR(VLOOKUP(A11,'マスタ'!$A:$F,3,FALSE),"")) | I11: =IF(A11="",0,IFERROR(VLOOKUP(A11,'マスタ'!$A:$F,4,FALSE),0)) | J11: =IF(A11="",0,IFERROR(VLOOKUP(A11,'マスタ'!$A:$F,5,FALSE),0)) | K11: =IF(A11="",0,ROUND(I11/160*1.25*H11,0)) | L11: =IF(A11="",0,IFERROR(VLOOKUP(A11,'マスタ'!$A:$F,6,FALSE),0)) | N11: =SUM(I11:M11) | U11: =SUM(O11:T11) | V11: =N11-U11
B12: =IF(A12="","",IFERROR(VLOOKUP(A12,'マスタ'!$A:$F,2,FALSE),"")) | C12: =IF(A12="","",IFERROR(VLOOKUP(A12,'マスタ'!$A:$F,3,FALSE),"")) | I12: =IF(A12="",0,IFERROR(VLOOKUP(A12,'マスタ'!$A:$F,4,FALSE),0)) | J12: =IF(A12="",0,IFERROR(VLOOKUP(A12,'マスタ'!$A:$F,5,FALSE),0)) | K12: =IF(A12="",0,ROUND(I12/160*1.25*H12,0)) | L12: =IF(A12="",0,IFERROR(VLOOKUP(A12,'マスタ'!$A:$F,6,FALSE),0)) | N12: =SUM(I12:M12) | U12: =SUM(O12:T12) | V12: =N12-U12
B13: =IF(A13="","",IFERROR(VLOOKUP(A13,'マスタ'!$A:$F,2,FALSE),"")) | C13: =IF(A13="","",IFERROR(VLOOKUP(A13,'マスタ'!$A:$F,3,FALSE),"")) | I13: =IF(A13="",0,IFERROR(VLOOKUP(A13,'マスタ'!$A:$F,4,FALSE),0)) | J13: =IF(A13="",0,IFERROR(VLOOKUP(A13,'マスタ'!$A:$F,5,FALSE),0)) | K13: =IF(A13="",0,ROUND(I13/160*1.25*H13,0)) | L13: =IF(A13="",0,IFERROR(VLOOKUP(A13,'マスタ'!$A:$F,6,FALSE),0)) | N13: =SUM(I13:M13) | U13: =SUM(O13:T13) | V13: =N13-U13
B14: =IF(A14="","",IFERROR(VLOOKUP(A14,'マスタ'!$A:$F,2,FALSE),"")) | C14: =IF(A14="","",IFERROR(VLOOKUP(A14,'マスタ'!$A:$F,3,FALSE),"")) | I14: =IF(A14="",0,IFERROR(VLOOKUP(A14,'マスタ'!$A:$F,4,FALSE),0)) | J14: =IF(A14="",0,IFERROR(VLOOKUP(A14,'マスタ'!$A:$F,5,FALSE),0)) | K14: =IF(A14="",0,ROUND(I14/160*1.25*H14,0)) | L14: =IF(A14="",0,IFERROR(VLOOKUP(A14,'マスタ'!$A:$F,6,FALSE),0)) | N14: =SUM(I14:M14) | U14: =SUM(O14:T14) | V14: =N14-U14
A15: 合 計 | D15: =SUM(D5:D14) | E15: =SUM(E5:E14) | F15: =SUM(F5:F14) | G15: =SUM(G5:G14) | H15: =SUM(H5:H14) | I15: =SUM(I5:I14) | J15: =SUM(J5:J14) | K15: =SUM(K5:K14) | ... V15: =SUM(V5:V14)

Sheet 7月
A1: 給与台帳 7月分
A2: 会社名：株式会社サンプル | L2: 作成日：2026年7月
A3: 基本情報 | D3: 勤 怠 情 報 | I3: 支 給 項 目 | O3: 控 除 項 目 | V3: 差引 支給額
A4: 従業員 番号 | B4: 氏名 | C4: 所属 | D4: 所定 労働日数 | E4: 出勤 日数 | F4: 欠勤 日数 | G4: 有給 取得日数 | H4: 残業 時間 | I4: 基本給 | J4: 役職 手当 | K4: 残業 手当 | L4: 通勤 手当 | M4: その他 手当 | N4: 支給 合計 | O4: 健康 保険 | P4: 厚生 年金 | Q4: 雇用 保険 | R4: 所得税 | S4: 住民税 | T4: その他 控除 | U4: 控除 合計 | V4: 差引 支給額
A5: 001 | B5: =IF(A5="","",IFERROR(VLOOKUP(A5,'マスタ'!$A:$F,2,FALSE),"")) | C5: =IF(A5="","",IFERROR(VLOOKUP(A5,'マスタ'!$A:$F,3,FALSE),"")) | D5: 20 | E5: 20 | F5: 0 | G5: 0 | H5: 10 | I5: =IF(A5="",0,IFERROR(VLOOKUP(A5,'マスタ'!$A:$F,4,FALSE),0)) | J5: =IF(A5="",0,IFERROR(VLOOKUP(A5,'マスタ'!$A:$F,5,FALSE),0)) | K5: =IF(A5="",0,ROUND(I5/160*1.25*H5,0)) | L5: =IF(A5="",0,IFERROR(VLOOKUP(A5,'マスタ'!$A:$F,6,FALSE),0)) | M5: 0 | N5: =SUM(I5:M5) | O5: 17500 | P5: 32490 | Q5: 2100 | R5: 8500 | S5: 12000 | T5: 0 | U5: =SUM(O5:T5) | V5: =N5-U5
A6: 002 | B6: =IF(A6="","",IFERROR(VLOOKUP(A6,'マスタ'!$A:$F,2,FALSE),"")) | C6: =IF(A6="","",IFERROR(VLOOKUP(A6,'マスタ'!$A:$F,3,FALSE),"")) | D6: 20 | E6: 19 | F6: 1 | G6: 1 | H6: 5 | I6: =IF(A6="",0,IFERROR(VLOOKUP(A6,'マスタ'!$A:$F,4,FALSE),0)) | J6: =IF(A6="",0,IFERROR(VLOOKUP(A6,'マスタ'!$A:$F,5,FALSE),0)) | K6: =IF(A6="",0,ROUND(I6/160*1.25*H6,0)) | L6: =IF(A6="",0,IFERROR(VLOOKUP(A6,'マスタ'!$A:$F,6,FALSE),0)) | M6: 0 | N6: =SUM(I6:M6) | O6: 14000 | P6: 25990 | Q6: 1680 | R6: 5500 | S6: 9000 | T6: 0 | U6: =SUM(O6:T6) | V6: =N6-U6
A7: 003 | B7: =IF(A7="","",IFERROR(VLOOKUP(A7,'マスタ'!$A:$F,2,FALSE),"")) | C7: =IF(A7="","",IFERROR(VLOOKUP(A7,'マスタ'!$A:$F,3,FALSE),"")) | D7: 20 | E7: 20 | F7: 0 | G7: 2 | H7: 15 | I7: =IF(A7="",0,IFERROR(VLOOKUP(A7,'マスタ'!$A:$F,4,FALSE),0)) | J7: =IF(A7="",0,IFERROR(VLOOKUP(A7,'マスタ'!$A:$F,5,FALSE),0)) | K7: =IF(A7="",0,ROUND(I7/160*1.25*H7,0)) | L7: =IF(A7="",0,IFERROR(VLOOKUP(A7,'マスタ'!$A:$F,6,FALSE),0)) | M7: 0 | N7: =SUM(I7:M7) | O7: 16000 | P7: 29730 | Q7: 1920 | R7: 7000 | S7: 10500 | T7: 0 | U7: =SUM(O7:T7) | V7: =N7-U7
B8: =IF(A8="","",IFERROR(VLOOKUP(A8,'マスタ'!$A:$F,2,FALSE),"")) | C8: =IF(A8="","",IFERROR(VLOOKUP(A8,'マスタ'!$A:$F,3,FALSE),"")) | I8: =IF(A8="",0,IFERROR(VLOOKUP(A8,'マスタ'!$A:$F,4,FALSE),0)) | J8: =IF(A8="",0,IFERROR(VLOOKUP(A8,'マスタ'!$A:$F,5,FALSE),0)) | K8: =IF(A8="",0,ROUND(I8/160*1.25*H8,0)) | L8: =IF(A8="",0,IFERROR(VLOOKUP(A8,'マスタ'!$A:$F,6,FALSE),0)) | N8: =SUM(I8:M8) | U8: =SUM(O8:T8) | V8: =N8-U8
B9: =IF(A9="","",IFERROR(VLOOKUP(A9,'マスタ'!$A:$F,2,FALSE),"")) | C9: =IF(A9="","",IFERROR(VLOOKUP(A9,'マスタ'!$A:$F,3,FALSE),"")) | I9: =IF(A9="",0,IFERROR(VLOOKUP(A9,'マスタ'!$A:$F,4,FALSE),0)) | J9: =IF(A9="",0,IFERROR(VLOOKUP(A9,'マスタ'!$A:$F,5,FALSE),0)) | K9: =IF(A9="",0,ROUND(I9/160*1.25*H9,0)) | L9: =IF(A9="",0,IFERROR(VLOOKUP(A9,'マスタ'!$A:$F,6,FALSE),0)) | N9: =SUM(I9:M9) | U9: =SUM(O9:T9) | V9: =N9-U9
B10: =IF(A10="","",IFERROR(VLOOKUP(A10,'マスタ'!$A:$F,2,FALSE),"")) | C10: =IF(A10="","",IFERROR(VLOOKUP(A10,'マスタ'!$A:$F,3,FALSE),"")) | I10: =IF(A10="",0,IFERROR(VLOOKUP(A10,'マスタ'!$A:$F,4,FALSE),0)) | J10: =IF(A10="",0,IFERROR(VLOOKUP(A10,'マスタ'!$A:$F,5,FALSE),0)) | K10: =IF(A10="",0,ROUND(I10/160*1.25*H10,0)) | L10: =IF(A10="",0,IFERROR(VLOOKUP(A10,'マスタ'!$A:$F,6,FALSE),0)) | N10: =SUM(I10:M10) | U10: =SUM(O10:T10) | V10: =N10-U10
B11: =IF(A11="","",IFERROR(VLOOKUP(A11,'マスタ'!$A:$F,2,FALSE),"")) | C11: =IF(A11="","",IFERROR(VLOOKUP(A11,'マスタ'!$A:$F,3,FALSE),"")) | I11: =IF(A11="",0,IFERROR(VLOOKUP(A11,'マスタ'!$A:$F,4,FALSE),0)) | J11: =IF(A11="",0,IFERROR(VLOOKUP(A11,'マスタ'!$A:$F,5,FALSE),0)) | K11: =IF(A11="",0,ROUND(I11/160*1.25*H11,0)) | L11: =IF(A11="",0,IFERROR(VLOOKUP(A11,'マスタ'!$A:$F,6,FALSE),0)) | N11: =SUM(I11:M11) | U11: =SUM(O11:T11) | V11: =N11-U11
B12: =IF(A12="","",IFERROR(VLOOKUP(A12,'マスタ'!$A:$F,2,FALSE),"")) | C12: =IF(A12="","",IFERROR(VLOOKUP(A12,'マスタ'!$A:$F,3,FALSE),"")) | I12: =IF(A12="",0,IFERROR(VLOOKUP(A12,'マスタ'!$A:$F,4,FALSE),0)) | J12: =IF(A12="",0,IFERROR(VLOOKUP(A12,'マスタ'!$A:$F,5,FALSE),0)) | K12: =IF(A12="",0,ROUND(I12/160*1.25*H12,0)) | L12: =IF(A12="",0,IFERROR(VLOOKUP(A12,'マスタ'!$A:$F,6,FALSE),0)) | N12: =SUM(I12:M12) | U12: =SUM(O12:T12) | V12: =N12-U12
B13: =IF(A13="","",IFERROR(VLOOKUP(A13,'マスタ'!$A:$F,2,FALSE),"")) | C13: =IF(A13="","",IFERROR(VLOOKUP(A13,'マスタ'!$A:$F,3,FALSE),"")) | I13: =IF(A13="",0,IFERROR(VLOOKUP(A13,'マスタ'!$A:$F,4,FALSE),0)) | J13: =IF(A13="",0,IFERROR(VLOOKUP(A13,'マスタ'!$A:$F,5,FALSE),0)) | K13: =IF(A13="",0,ROUND(I13/160*1.25*H13,0)) | L13: =IF(A13="",0,IFERROR(VLOOKUP(A13,'マスタ'!$A:$F,6,FALSE),0)) | N13: =SUM(I13:M13) | U13: =SUM(O13:T13) | V13: =N13-U13
B14: =IF(A14="","",IFERROR(VLOOKUP(A14,'マスタ'!$A:$F,2,FALSE),"")) | C14: =IF(A14="","",IFERROR(VLOOKUP(A14,'マスタ'!$A:$F,3,FALSE),"")) | I14: =IF(A14="",0,IFERROR(VLOOKUP(A14,'マスタ'!$A:$F,4,FALSE),0)) | J14: =IF(A14="",0,IFERROR(VLOOKUP(A14,'マスタ'!$A:$F,5,FALSE),0)) | K14: =IF(A14="",0,ROUND(I14/160*1.25*H14,0)) | L14: =IF(A14="",0,IFERROR(VLOOKUP(A14,'マスタ'!$A:$F,6,FALSE),0)) | N14: =SUM(I14:M14) | U14: =SUM(O14:T14) | V14: =N14-U14
A15: 合 計 | D15: =SUM(D5:D14) | E15: =SUM(E5:E14) | F15: =SUM(F5:F14) | G15: =SUM(G5:G14) | H15: =SUM(H5:H14) | I15: =SUM(I5:I14) | J15: =SUM(J5:J14) | K15: =SUM(K5:K14) | ... V15: =SUM(V5:V14)

Sheet 8月
A1: 給与台帳 8月分
A2: 会社名：株式会社サンプル | L2: 作成日：2026年8月
A3: 基本情報 | D3: 勤 怠 情 報 | I3: 支 給 項 目 | O3: 控 除 項 目 | V3: 差引 支給額
A4: 従業員 番号 | B4: 氏名 | C4: 所属 | D4: 所定 労働日数 | E4: 出勤 日数 | F4: 欠勤 日数 | G4: 有給 取得日数 | H4: 残業 時間 | I4: 基本給 | J4: 役職 手当 | K4: 残業 手当 | L4: 通勤 手当 | M4: その他 手当 | N4: 支給 合計 | O4: 健康 保険 | P4: 厚生 年金 | Q4: 雇用 保険 | R4: 所得税 | S4: 住民税 | T4: その他 控除 | U4: 控除 合計 | V4: 差引 支給額
A5: 001 | B5: =IF(A5="","",IFERROR(VLOOKUP(A5,'マスタ'!$A:$F,2,FALSE),"")) | C5: =IF(A5="","",IFERROR(VLOOKUP(A5,'マスタ'!$A:$F,3,FALSE),"")) | D5: 20 | E5: 20 | F5: 0 | G5: 0 | H5: 10 | I5: =IF(A5="",0,IFERROR(VLOOKUP(A5,'マスタ'!$A:$F,4,FALSE),0)) | J5: =IF(A5="",0,IFERROR(VLOOKUP(A5,'マスタ'!$A:$F,5,FALSE),0)) | K5: =IF(A5="",0,ROUND(I5/160*1.25*H5,0)) | L5: =IF(A5="",0,IFERROR(VLOOKUP(A5,'マスタ'!$A:$F,6,FALSE),0)) | M5: 0 | N5: =SUM(I5:M5) | O5: 17500 | P5: 32490 | Q5: 2100 | R5: 8500 | S5: 12000 | T5: 0 | U5: =SUM(O5:T5) | V5: =N5-U5
A6: 002 | B6: =IF(A6="","",IFERROR(VLOOKUP(A6,'マスタ'!$A:$F,2,FALSE),"")) | C6: =IF(A6="","",IFERROR(VLOOKUP(A6,'マスタ'!$A:$F,3,FALSE),"")) | D6: 20 | E6: 19 | F6: 1 | G6: 1 | H6: 5 | I6: =IF(A6="",0,IFERROR(VLOOKUP(A6,'マスタ'!$A:$F,4,FALSE),0)) | J6: =IF(A6="",0,IFERROR(VLOOKUP(A6,'マスタ'!$A:$F,5,FALSE),0)) | K6: =IF(A6="",0,ROUND(I6/160*1.25*H6,0)) | L6: =IF(A6="",0,IFERROR(VLOOKUP(A6,'マスタ'!$A:$F,6,FALSE),0)) | M6: 0 | N6: =SUM(I6:M6) | O6: 14000 | P6: 25990 | Q6: 1680 | R6: 5500 | S6: 9000 | T6: 0 | U6: =SUM(O6:T6) | V6: =N6-U6
A7: 003 | B7: =IF(A7="","",IFERROR(VLOOKUP(A7,'マスタ'!$A:$F,2,FALSE),"")) | C7: =IF(A7="","",IFERROR(VLOOKUP(A7,'マスタ'!$A:$F,3,FALSE),"")) | D7: 20 | E7: 20 | F7: 0 | G7: 2 | H7: 15 | I7: =IF(A7="",0,IFERROR(VLOOKUP(A7,'マスタ'!$A:$F,4,FALSE),0)) | J7: =IF(A7="",0,IFERROR(VLOOKUP(A7,'マスタ'!$A:$F,5,FALSE),0)) | K7: =IF(A7="",0,ROUND(I7/160*1.25*H7,0)) | L7: =IF(A7="",0,IFERROR(VLOOKUP(A7,'マスタ'!$A:$F,6,FALSE),0)) | M7: 0 | N7: =SUM(I7:M7) | O7: 16000 | P7: 29730 | Q7: 1920 | R7: 7000 | S7: 10500 | T7: 0 | U7: =SUM(O7:T7) | V7: =N7-U7
B8: =IF(A8="","",IFERROR(VLOOKUP(A8,'マスタ'!$A:$F,2,FALSE),"")) | C8: =IF(A8="","",IFERROR(VLOOKUP(A8,'マスタ'!$A:$F,3,FALSE),"")) | I8: =IF(A8="",0,IFERROR(VLOOKUP(A8,'マスタ'!$A:$F,4,FALSE),0)) | J8: =IF(A8="",0,IFERROR(VLOOKUP(A8,'マスタ'!$A:$F,5,FALSE),0)) | K8: =IF(A8="",0,ROUND(I8/160*1.25*H8,0)) | L8: =IF(A8="",0,IFERROR(VLOOKUP(A8,'マスタ'!$A:$F,6,FALSE),0)) | N8: =SUM(I8:M8) | U8: =SUM(O8:T8) | V8: =N8-U8
B9: =IF(A9="","",IFERROR(VLOOKUP(A9,'マスタ'!$A:$F,2,FALSE),"")) | C9: =IF(A9="","",IFERROR(VLOOKUP(A9,'マスタ'!$A:$F,3,FALSE),"")) | I9: =IF(A9="",0,IFERROR(VLOOKUP(A9,'マスタ'!$A:$F,4,FALSE),0)) | J9: =IF(A9="",0,IFERROR(VLOOKUP(A9,'マスタ'!$A:$F,5,FALSE),0)) | K9: =IF(A9="",0,ROUND(I9/160*1.25*H9,0)) | L9: =IF(A9="",0,IFERROR(VLOOKUP(A9,'マスタ'!$A:$F,6,FALSE),0)) | N9: =SUM(I9:M9) | U9: =SUM(O9:T9) | V9: =N9-U9
B10: =IF(A10="","",IFERROR(VLOOKUP(A10,'マスタ'!$A:$F,2,FALSE),"")) | C10: =IF(A10="","",IFERROR(VLOOKUP(A10,'マスタ'!$A:$F,3,FALSE),"")) | I10: =IF(A10="",0,IFERROR(VLOOKUP(A10,'マスタ'!$A:$F,4,FALSE),0)) | J10: =IF(A10="",0,IFERROR(VLOOKUP(A10,'マスタ'!$A:$F,5,FALSE),0)) | K10: =IF(A10="",0,ROUND(I10/160*1.25*H10,0)) | L10: =IF(A10="",0,IFERROR(VLOOKUP(A10,'マスタ'!$A:$F,6,FALSE),0)) | N10: =SUM(I10:M10) | U10: =SUM(O10:T10) | V10: =N10-U10
B11: =IF(A11="","",IFERROR(VLOOKUP(A11,'マスタ'!$A:$F,2,FALSE),"")) | C11: =IF(A11="","",IFERROR(VLOOKUP(A11,'マスタ'!$A:$F,3,FALSE),"")) | I11: =IF(A11="",0,IFERROR(VLOOKUP(A11,'マスタ'!$A:$F,4,FALSE),0)) | J11: =IF(A11="",0,IFERROR(VLOOKUP(A11,'マスタ'!$A:$F,5,FALSE),0)) | K11: =IF(A11="",0,ROUND(I11/160*1.25*H11,0)) | L11: =IF(A11="",0,IFERROR(VLOOKUP(A11,'マスタ'!$A:$F,6,FALSE),0)) | N11: =SUM(I11:M11) | U11: =SUM(O11:T11) | V11: =N11-U11
B12: =IF(A12="","",IFERROR(VLOOKUP(A12,'マスタ'!$A:$F,2,FALSE),"")) | C12: =IF(A12="","",IFERROR(VLOOKUP(A12,'マスタ'!$A:$F,3,FALSE),"")) | I12: =IF(A12="",0,IFERROR(VLOOKUP(A12,'マスタ'!$A:$F,4,FALSE),0)) | J12: =IF(A12="",0,IFERROR(VLOOKUP(A12,'マスタ'!$A:$F,5,FALSE),0)) | K12: =IF(A12="",0,ROUND(I12/160*1.25*H12,0)) | L12: =IF(A12="",0,IFERROR(VLOOKUP(A12,'マスタ'!$A:$F,6,FALSE),0)) | N12: =SUM(I12:M12) | U12: =SUM(O12:T12) | V12: =N12-U12
B13: =IF(A13="","",IFERROR(VLOOKUP(A13,'マスタ'!$A:$F,2,FALSE),"")) | C13: =IF(A13="","",IFERROR(VLOOKUP(A13,'マスタ'!$A:$F,3,FALSE),"")) | I13: =IF(A13="",0,IFERROR(VLOOKUP(A13,'マスタ'!$A:$F,4,FALSE),0)) | J13: =IF(A13="",0,IFERROR(VLOOKUP(A13,'マスタ'!$A:$F,5,FALSE),0)) | K13: =IF(A13="",0,ROUND(I13/160*1.25*H13,0)) | L13: =IF(A13="",0,IFERROR(VLOOKUP(A13,'マスタ'!$A:$F,6,FALSE),0)) | N13: =SUM(I13:M13) | U13: =SUM(O13:T13) | V13: =N13-U13
B14: =IF(A14="","",IFERROR(VLOOKUP(A14,'マスタ'!$A:$F,2,FALSE),"")) | C14: =IF(A14="","",IFERROR(VLOOKUP(A14,'マスタ'!$A:$F,3,FALSE),"")) | I14: =IF(A14="",0,IFERROR(VLOOKUP(A14,'マスタ'!$A:$F,4,FALSE),0)) | J14: =IF(A14="",0,IFERROR(VLOOKUP(A14,'マスタ'!$A:$F,5,FALSE),0)) | K14: =IF(A14="",0,ROUND(I14/160*1.25*H14,0)) | L14: =IF(A14="",0,IFERROR(VLOOKUP(A14,'マスタ'!$A:$F,6,FALSE),0)) | N14: =SUM(I14:M14) | U14: =SUM(O14:T14) | V14: =N14-U14
A15: 合 計 | D15: =SUM(D5:D14) | E15: =SUM(E5:E14) | F15: =SUM(F5:F14) | G15: =SUM(G5:G14) | H15: =SUM(H5:H14) | I15: =SUM(I5:I14) | J15: =SUM(J5:J14) | K15: =SUM(K5:K14) | ... V15: =SUM(V5:V14)

Sheet 9月
A1: 給与台帳 9月分
A2: 会社名：株式会社サンプル | L2: 作成日：2026年9月
A3: 基本情報 | D3: 勤 怠 情 報 | I3: 支 給 項 目 | O3: 控 除 項 目 | V3: 差引 支給額
A4: 従業員 番号 | B4: 氏名 | C4: 所属 | D4: 所定 労働日数 | E4: 出勤 日数 | F4: 欠勤 日数 | G4: 有給 取得日数 | H4: 残業 時間 | I4: 基本給 | J4: 役職 手当 | K4: 残業 手当 | L4: 通勤 手当 | M4: その他 手当 | N4: 支給 合計 | O4: 健康 保険 | P4: 厚生 年金 | Q4: 雇用 保険 | R4: 所得税 | S4: 住民税 | T4: その他 控除 | U4: 控除 合計 | V4: 差引 支給額
A5: 001 | B5: =IF(A5="","",IFERROR(VLOOKUP(A5,'マスタ'!$A:$F,2,FALSE),"")) | C5: =IF(A5="","",IFERROR(VLOOKUP(A5,'マスタ'!$A:$F,3,FALSE),"")) | D5: 20 | E5: 20 | F5: 0 | G5: 0 | H5: 10 | I5: =IF(A5="",0,IFERROR(VLOOKUP(A5,'マスタ'!$A:$F,4,FALSE),0)) | J5: =IF(A5="",0,IFERROR(VLOOKUP(A5,'マスタ'!$A:$F,5,FALSE),0)) | K5: =IF(A5="",0,ROUND(I5/160*1.25*H5,0)) | L5: =IF(A5="",0,IFERROR(VLOOKUP(A5,'マスタ'!$A:$F,6,FALSE),0)) | M5: 0 | N5: =SUM(I5:M5) | O5: 17500 | P5: 32490 | Q5: 2100 | R5: 8500 | S5: 12000 | T5: 0 | U5: =SUM(O5:T5) | V5: =N5-U5
A6: 002 | B6: =IF(A6="","",IFERROR(VLOOKUP(A6,'マスタ'!$A:$F,2,FALSE),"")) | C6: =IF(A6="","",IFERROR(VLOOKUP(A6,'マスタ'!$A:$F,3,FALSE),"")) | D6: 20 | E6: 19 | F6: 1 | G6: 1 | H6: 5 | I6: =IF(A6="",0,IFERROR(VLOOKUP(A6,'マスタ'!$A:$F,4,FALSE),0)) | J6: =IF(A6="",0,IFERROR(VLOOKUP(A6,'マスタ'!$A:$F,5,FALSE),0)) | K6: =IF(A6="",0,ROUND(I6/160*1.25*H6,0)) | L6: =IF(A6="",0,IFERROR(VLOOKUP(A6,'マスタ'!$A:$F,6,FALSE),0)) | M6: 0 | N6: =SUM(I6:M6) | O6: 14000 | P6: 25990 | Q6: 1680 | R6: 5500 | S6: 9000 | T6: 0 | U6: =SUM(O6:T6) | V6: =N6-U6
A7: 003 | B7: =IF(A7="","",IFERROR(VLOOKUP(A7,'マスタ'!$A:$F,2,FALSE),"")) | C7: =IF(A7="","",IFERROR(VLOOKUP(A7,'マスタ'!$A:$F,3,FALSE),"")) | D7: 20 | E7: 20 | F7: 0 | G7: 2 | H7: 15 | I7: =IF(A7="",0,IFERROR(VLOOKUP(A7,'マスタ'!$A:$F,4,FALSE),0)) | J7: =IF(A7="",0,IFERROR(VLOOKUP(A7,'マスタ'!$A:$F,5,FALSE),0)) | K7: =IF(A7="",0,ROUND(I7/160*1.25*H7,0)) | L7: =IF(A7="",0,IFERROR(VLOOKUP(A7,'マスタ'!$A:$F,6,FALSE),0)) | M7: 0 | N7: =SUM(I7:M7) | O7: 16000 | P7: 29730 | Q7: 1920 | R7: 7000 | S7: 10500 | T7: 0 | U7: =SUM(O7:T7) | V7: =N7-U7
B8: =IF(A8="","",IFERROR(VLOOKUP(A8,'マスタ'!$A:$F,2,FALSE),"")) | C8: =IF(A8="","",IFERROR(VLOOKUP(A8,'マスタ'!$A:$F,3,FALSE),"")) | I8: =IF(A8="",0,IFERROR(VLOOKUP(A8,'マスタ'!$A:$F,4,FALSE),0)) | J8: =IF(A8="",0,IFERROR(VLOOKUP(A8,'マスタ'!$A:$F,5,FALSE),0)) | K8: =IF(A8="",0,ROUND(I8/160*1.25*H8,0)) | L8: =IF(A8="",0,IFERROR(VLOOKUP(A8,'マスタ'!$A:$F,6,FALSE),0)) | N8: =SUM(I8:M8) | U8: =SUM(O8:T8) | V8: =N8-U8
B9: =IF(A9="","",IFERROR(VLOOKUP(A9,'マスタ'!$A:$F,2,FALSE),"")) | C9: =IF(A9="","",IFERROR(VLOOKUP(A9,'マスタ'!$A:$F,3,FALSE),"")) | I9: =IF(A9="",0,IFERROR(VLOOKUP(A9,'マスタ'!$A:$F,4,FALSE),0)) | J9: =IF(A9="",0,IFERROR(VLOOKUP(A9,'マスタ'!$A:$F,5,FALSE),0)) | K9: =IF(A9="",0,ROUND(I9/160*1.25*H9,0)) | L9: =IF(A9="",0,IFERROR(VLOOKUP(A9,'マスタ'!$A:$F,6,FALSE),0)) | N9: =SUM(I9:M9) | U9: =SUM(O9:T9) | V9: =N9-U9
B10: =IF(A10="","",IFERROR(VLOOKUP(A10,'マスタ'!$A:$F,2,FALSE),"")) | C10: =IF(A10="","",IFERROR(VLOOKUP(A10,'マスタ'!$A:$F,3,FALSE),"")) | I10: =IF(A10="",0,IFERROR(VLOOKUP(A10,'マスタ'!$A:$F,4,FALSE),0)) | J10: =IF(A10="",0,IFERROR(VLOOKUP(A10,'マスタ'!$A:$F,5,FALSE),0)) | K10: =IF(A10="",0,ROUND(I10/160*1.25*H10,0)) | L10: =IF(A10="",0,IFERROR(VLOOKUP(A10,'マスタ'!$A:$F,6,FALSE),0)) | N10: =SUM(I10:M10) | U10: =SUM(O10:T10) | V10: =N10-U10
B11: =IF(A11="","",IFERROR(VLOOKUP(A11,'マスタ'!$A:$F,2,FALSE),"")) | C11: =IF(A11="","",IFERROR(VLOOKUP(A11,'マスタ'!$A:$F,3,FALSE),"")) | I11: =IF(A11="",0,IFERROR(VLOOKUP(A11,'マスタ'!$A:$F,4,FALSE),0)) | J11: =IF(A11="",0,IFERROR(VLOOKUP(A11,'マスタ'!$A:$F,5,FALSE),0)) | K11: =IF(A11="",0,ROUND(I11/160*1.25*H11,0)) | L11: =IF(A11="",0,IFERROR(VLOOKUP(A11,'マスタ'!$A:$F,6,FALSE),0)) | N11: =SUM(I11:M11) | U11: =SUM(O11:T11) | V11: =N11-U11
B12: =IF(A12="","",IFERROR(VLOOKUP(A12,'マスタ'!$A:$F,2,FALSE),"")) | C12: =IF(A12="","",IFERROR(VLOOKUP(A12,'マスタ'!$A:$F,3,FALSE),"")) | I12: =IF(A12="",0,IFERROR(VLOOKUP(A12,'マスタ'!$A:$F,4,FALSE),0)) | J12: =IF(A12="",0,IFERROR(VLOOKUP(A12,'マスタ'!$A:$F,5,FALSE),0)) | K12: =IF(A12="",0,ROUND(I12/160*1.25*H12,0)) | L12: =IF(A12="",0,IFERROR(VLOOKUP(A12,'マスタ'!$A:$F,6,FALSE),0)) | N12: =SUM(I12:M12) | U12: =SUM(O12:T12) | V12: =N12-U12
B13: =IF(A13="","",IFERROR(VLOOKUP(A13,'マスタ'!$A:$F,2,FALSE),"")) | C13: =IF(A13="","",IFERROR(VLOOKUP(A13,'マスタ'!$A:$F,3,FALSE),"")) | I13: =IF(A13="",0,IFERROR(VLOOKUP(A13,'マスタ'!$A:$F,4,FALSE),0)) | J13: =IF(A13="",0,IFERROR(VLOOKUP(A13,'マスタ'!$A:$F,5,FALSE),0)) | K13: =IF(A13="",0,ROUND(I13/160*1.25*H13,0)) | L13: =IF(A13="",0,IFERROR(VLOOKUP(A13,'マスタ'!$A:$F,6,FALSE),0)) | N13: =SUM(I13:M13) | U13: =SUM(O13:T13) | V13: =N13-U13
B14: =IF(A14="","",IFERROR(VLOOKUP(A14,'マスタ'!$A:$F,2,FALSE),"")) | C14: =IF(A14="","",IFERROR(VLOOKUP(A14,'マスタ'!$A:$F,3,FALSE),"")) | I14: =IF(A14="",0,IFERROR(VLOOKUP(A14,'マスタ'!$A:$F,4,FALSE),0)) | J14: =IF(A14="",0,IFERROR(VLOOKUP(A14,'マスタ'!$A:$F,5,FALSE),0)) | K14: =IF(A14="",0,ROUND(I14/160*1.25*H14,0)) | L14: =IF(A14="",0,IFERROR(VLOOKUP(A14,'マスタ'!$A:$F,6,FALSE),0)) | N14: =SUM(I14:M14) | U14: =SUM(O14:T14) | V14: =N14-U14
A15: 合 計 | D15: =SUM(D5:D14) | E15: =SUM(E5:E14) | F15: =SUM(F5:F14) | G15: =SUM(G5:G14) | H15: =SUM(H5:H14) | I15: =SUM(I5:I14) | J15: =SUM(J5:J14) | K15: =SUM(K5:K14) | ... V15: =SUM(V5:V14)

Sheet 10月
A1: 給与台帳 10月分
A2: 会社名：株式会社サンプル | L2: 作成日：2026年10月
A3: 基本情報 | D3: 勤 怠 情 報 | I3: 支 給 項 目 | O3: 控 除 項 目 | V3: 差引 支給額
A4: 従業員 番号 | B4: 氏名 | C4: 所属 | D4: 所定 労働日数 | E4: 出勤 日数 | F4: 欠勤 日数 | G4: 有給 取得日数 | H4: 残業 時間 | I4: 基本給 | J4: 役職 手当 | K4: 残業 手当 | L4: 通勤 手当 | M4: その他 手当 | N4: 支給 合計 | O4: 健康 保険 | P4: 厚生 年金 | Q4: 雇用 保険 | R4: 所得税 | S4: 住民税 | T4: その他 控除 | U4: 控除 合計 | V4: 差引 支給額
A5: 001 | B5: =IF(A5="","",IFERROR(VLOOKUP(A5,'マスタ'!$A:$F,2,FALSE),"")) | C5: =IF(A5="","",IFERROR(VLOOKUP(A5,'マスタ'!$A:$F,3,FALSE),"")) | D5: 20 | E5: 20 | F5: 0 | G5: 0 | H5: 10 | I5: =IF(A5="",0,IFERROR(VLOOKUP(A5,'マスタ'!$A:$F,4,FALSE),0)) | J5: =IF(A5="",0,IFERROR(VLOOKUP(A5,'マスタ'!$A:$F,5,FALSE),0)) | K5: =IF(A5="",0,ROUND(I5/160*1.25*H5,0)) | L5: =IF(A5="",0,IFERROR(VLOOKUP(A5,'マスタ'!$A:$F,6,FALSE),0)) | M5: 0 | N5: =SUM(I5:M5) | O5: 17500 | P5: 32490 | Q5: 2100 | R5: 8500 | S5: 12000 | T5: 0 | U5: =SUM(O5:T5) | V5: =N5-U5
A6: 002 | B6: =IF(A6="","",IFERROR(VLOOKUP(A6,'マスタ'!$A:$F,2,FALSE),"")) | C6: =IF(A6="","",IFERROR(VLOOKUP(A6,'マスタ'!$A:$F,3,FALSE),"")) | D6: 20 | E6: 19 | F6: 1 | G6: 1 | H6: 5 | I6: =IF(A6="",0,IFERROR(VLOOKUP(A6,'マスタ'!$A:$F,4,FALSE),0)) | J6: =IF(A6="",0,IFERROR(VLOOKUP(A6,'マスタ'!$A:$F,5,FALSE),0)) | K6: =IF(A6="",0,ROUND(I6/160*1.25*H6,0)) | L6: =IF(A6="",0,IFERROR(VLOOKUP(A6,'マスタ'!$A:$F,6,FALSE),0)) | M6: 0 | N6: =SUM(I6:M6) | O6: 14000 | P6: 25990 | Q6: 1680 | R6: 5500 | S6: 9000 | T6: 0 | U6: =SUM(O6:T6) | V6: =N6-U6
A7: 003 | B7: =IF(A7="","",IFERROR(VLOOKUP(A7,'マスタ'!$A:$F,2,FALSE),"")) | C7: =IF(A7="","",IFERROR(VLOOKUP(A7,'マスタ'!$A:$F,3,FALSE),"")) | D7: 20 | E7: 20 | F7: 0 | G7: 2 | H7: 15 | I7: =IF(A7="",0,IFERROR(VLOOKUP(A7,'マスタ'!$A:$F,4,FALSE),0)) | J7: =IF(A7="",0,IFERROR(VLOOKUP(A7,'マスタ'!$A:$F,5,FALSE),0)) | K7: =IF(A7="",0,ROUND(I7/160*1.25*H7,0)) | L7: =IF(A7="",0,IFERROR(VLOOKUP(A7,'マスタ'!$A:$F,6,FALSE),0)) | M7: 0 | N7: =SUM(I7:M7) | O7: 16000 | P7: 29730 | Q7: 1920 | R7: 7000 | S7: 10500 | T7: 0 | U7: =SUM(O7:T7) | V7: =N7-U7
B8: =IF(A8="","",IFERROR(VLOOKUP(A8,'マスタ'!$A:$F,2,FALSE),"")) | C8: =IF(A8="","",IFERROR(VLOOKUP(A8,'マスタ'!$A:$F,3,FALSE),"")) | I8: =IF(A8="",0,IFERROR(VLOOKUP(A8,'マスタ'!$A:$F,4,FALSE),0)) | J8: =IF(A8="",0,IFERROR(VLOOKUP(A8,'マスタ'!$A:$F,5,FALSE),0)) | K8: =IF(A8="",0,ROUND(I8/160*1.25*H8,0)) | L8: =IF(A8="",0,IFERROR(VLOOKUP(A8,'マスタ'!$A:$F,6,FALSE),0)) | N8: =SUM(I8:M8) | U8: =SUM(O8:T8) | V8: =N8-U8
B9: =IF(A9="","",IFERROR(VLOOKUP(A9,'マスタ'!$A:$F,2,FALSE),"")) | C9: =IF(A9="","",IFERROR(VLOOKUP(A9,'マスタ'!$A:$F,3,FALSE),"")) | I9: =IF(A9="",0,IFERROR(VLOOKUP(A9,'マスタ'!$A:$F,4,FALSE),0)) | J9: =IF(A9="",0,IFERROR(VLOOKUP(A9,'マスタ'!$A:$F,5,FALSE),0)) | K9: =IF(A9="",0,ROUND(I9/160*1.25*H9,0)) | L9: =IF(A9="",0,IFERROR(VLOOKUP(A9,'マスタ'!$A:$F,6,FALSE),0)) | N9: =SUM(I9:M9) | U9: =SUM(O9:T9) | V9: =N9-U9
B10: =IF(A10="","",IFERROR(VLOOKUP(A10,'マスタ'!$A:$F,2,FALSE),"")) | C10: =IF(A10="","",IFERROR(VLOOKUP(A10,'マスタ'!$A:$F,3,FALSE),"")) | I10: =IF(A10="",0,IFERROR(VLOOKUP(A10,'マスタ'!$A:$F,4,FALSE),0)) | J10: =IF(A10="",0,IFERROR(VLOOKUP(A10,'マスタ'!$A:$F,5,FALSE),0)) | K10: =IF(A10="",0,ROUND(I10/160*1.25*H10,0)) | L10: =IF(A10="",0,IFERROR(VLOOKUP(A10,'マスタ'!$A:$F,6,FALSE),0)) | N10: =SUM(I10:M10) | U10: =SUM(O10:T10) | V10: =N10-U10
B11: =IF(A11="","",IFERROR(VLOOKUP(A11,'マスタ'!$A:$F,2,FALSE),"")) | C11: =IF(A11="","",IFERROR(VLOOKUP(A11,'マスタ'!$A:$F,3,FALSE),"")) | I11: =IF(A11="",0,IFERROR(VLOOKUP(A11,'マスタ'!$A:$F,4,FALSE),0)) | J11: =IF(A11="",0,IFERROR(VLOOKUP(A11,'マスタ'!$A:$F,5,FALSE),0)) | K11: =IF(A11="",0,ROUND(I11/160*1.25*H11,0)) | L11: =IF(A11="",0,IFERROR(VLOOKUP(A11,'マスタ'!$A:$F,6,FALSE),0)) | N11: =SUM(I11:M11) | U11: =SUM(O11:T11) | V11: =N11-U11
B12: =IF(A12="","",IFERROR(VLOOKUP(A12,'マスタ'!$A:$F,2,FALSE),"")) | C12: =IF(A12="","",IFERROR(VLOOKUP(A12,'マスタ'!$A:$F,3,FALSE),"")) | I12: =IF(A12="",0,IFERROR(VLOOKUP(A12,'マスタ'!$A:$F,4,FALSE),0)) | J12: =IF(A12="",0,IFERROR(VLOOKUP(A12,'マスタ'!$A:$F,5,FALSE),0)) | K12: =IF(A12="",0,ROUND(I12/160*1.25*H12,0)) | L12: =IF(A12="",0,IFERROR(VLOOKUP(A12,'マスタ'!$A:$F,6,FALSE),0)) | N12: =SUM(I12:M12) | U12: =SUM(O12:T12) | V12: =N12-U12
B13: =IF(A13="","",IFERROR(VLOOKUP(A13,'マスタ'!$A:$F,2,FALSE),"")) | C13: =IF(A13="","",IFERROR(VLOOKUP(A13,'マスタ'!$A:$F,3,FALSE),"")) | I13: =IF(A13="",0,IFERROR(VLOOKUP(A13,'マスタ'!$A:$F,4,FALSE),0)) | J13: =IF(A13="",0,IFERROR(VLOOKUP(A13,'マスタ'!$A:$F,5,FALSE),0)) | K13: =IF(A13="",0,ROUND(I13/160*1.25*H13,0)) | L13: =IF(A13="",0,IFERROR(VLOOKUP(A13,'マスタ'!$A:$F,6,FALSE),0)) | N13: =SUM(I13:M13) | U13: =SUM(O13:T13) | V13: =N13-U13
B14: =IF(A14="","",IFERROR(VLOOKUP(A14,'マスタ'!$A:$F,2,FALSE),"")) | C14: =IF(A14="","",IFERROR(VLOOKUP(A14,'マスタ'!$A:$F,3,FALSE),"")) | I14: =IF(A14="",0,IFERROR(VLOOKUP(A14,'マスタ'!$A:$F,4,FALSE),0)) | J14: =IF(A14="",0,IFERROR(VLOOKUP(A14,'マスタ'!$A:$F,5,FALSE),0)) | K14: =IF(A14="",0,ROUND(I14/160*1.25*H14,0)) | L14: =IF(A14="",0,IFERROR(VLOOKUP(A14,'マスタ'!$A:$F,6,FALSE),0)) | N14: =SUM(I14:M14) | U14: =SUM(O14:T14) | V14: =N14-U14
A15: 合 計 | D15: =SUM(D5:D14) | E15: =SUM(E5:E14) | F15: =SUM(F5:F14) | G15: =SUM(G5:G14) | H15: =SUM(H5:H14) | I15: =SUM(I5:I14) | J15: =SUM(J5:J14) | K15: =SUM(K5:K14) | ... V15: =SUM(V5:V14)

Sheet 11月
A1: 給与台帳 11月分
A2: 会社名：株式会社サンプル | L2: 作成日：2026年11月
A3: 基本情報 | D3: 勤 怠 情 報 | I3: 支 給 項 目 | O3: 控 除 項 目 | V3: 差引 支給額
A4: 従業員 番号 | B4: 氏名 | C4: 所属 | D4: 所定 労働日数 | E4: 出勤 日数 | F4: 欠勤 日数 | G4: 有給 取得日数 | H4: 残業 時間 | I4: 基本給 | J4: 役職 手当 | K4: 残業 手当 | L4: 通勤 手当 | M4: その他 手当 | N4: 支給 合計 | O4: 健康 保険 | P4: 厚生 年金 | Q4: 雇用 保険 | R4: 所得税 | S4: 住民税 | T4: その他 控除 | U4: 控除 合計 | V4: 差引 支給額
A5: 001 | B5: =IF(A5="","",IFERROR(VLOOKUP(A5,'マスタ'!$A:$F,2,FALSE),"")) | C5: =IF(A5="","",IFERROR(VLOOKUP(A5,'マスタ'!$A:$F,3,FALSE),"")) | D5: 20 | E5: 20 | F5: 0 | G5: 0 | H5: 10 | I5: =IF(A5="",0,IFERROR(VLOOKUP(A5,'マスタ'!$A:$F,4,FALSE),0)) | J5: =IF(A5="",0,IFERROR(VLOOKUP(A5,'マスタ'!$A:$F,5,FALSE),0)) | K5: =IF(A5="",0,ROUND(I5/160*1.25*H5,0)) | L5: =IF(A5="",0,IFERROR(VLOOKUP(A5,'マスタ'!$A:$F,6,FALSE),0)) | M5: 0 | N5: =SUM(I5:M5) | O5: 17500 | P5: 32490 | Q5: 2100 | R5: 8500 | S5: 12000 | T5: 0 | U5: =SUM(O5:T5) | V5: =N5-U5
A6: 002 | B6: =IF(A6="","",IFERROR(VLOOKUP(A6,'マスタ'!$A:$F,2,FALSE),"")) | C6: =IF(A6="","",IFERROR(VLOOKUP(A6,'マスタ'!$A:$F,3,FALSE),"")) | D6: 20 | E6: 19 | F6: 1 | G6: 1 | H6: 5 | I6: =IF(A6="",0,IFERROR(VLOOKUP(A6,'マスタ'!$A:$F,4,FALSE),0)) | J6: =IF(A6="",0,IFERROR(VLOOKUP(A6,'マスタ'!$A:$F,5,FALSE),0)) | K6: =IF(A6="",0,ROUND(I6/160*1.25*H6,0)) | L6: =IF(A6="",0,IFERROR(VLOOKUP(A6,'マスタ'!$A:$F,6,FALSE),0)) | M6: 0 | N6: =SUM(I6:M6) | O6: 14000 | P6: 25990 | Q6: 1680 | R6: 5500 | S6: 9000 | T6: 0 | U6: =SUM(O6:T6) | V6: =N6-U6
A7: 003 | B7: =IF(A7="","",IFERROR(VLOOKUP(A7,'マスタ'!$A:$F,2,FALSE),"")) | C7: =IF(A7="","",IFERROR(VLOOKUP(A7,'マスタ'!$A:$F,3,FALSE),"")) | D7: 20 | E7: 20 | F7: 0 | G7: 2 | H7: 15 | I7: =IF(A7="",0,IFERROR(VLOOKUP(A7,'マスタ'!$A:$F,4,FALSE),0)) | J7: =IF(A7="",0,IFERROR(VLOOKUP(A7,'マスタ'!$A:$F,5,FALSE),0)) | K7: =IF(A7="",0,ROUND(I7/160*1.25*H7,0)) | L7: =IF(A7="",0,IFERROR(VLOOKUP(A7,'マスタ'!$A:$F,6,FALSE),0)) | M7: 0 | N7: =SUM(I7:M7) | O7: 16000 | P7: 29730 | Q7: 1920 | R7: 7000 | S7: 10500 | T7: 0 | U7: =SUM(O7:T7) | V7: =N7-U7
B8: =IF(A8="","",IFERROR(VLOOKUP(A8,'マスタ'!$A:$F,2,FALSE),"")) | C8: =IF(A8="","",IFERROR(VLOOKUP(A8,'マスタ'!$A:$F,3,FALSE),"")) | I8: =IF(A8="",0,IFERROR(VLOOKUP(A8,'マスタ'!$A:$F,4,FALSE),0)) | J8: =IF(A8="",0,IFERROR(VLOOKUP(A8,'マスタ'!$A:$F,5,FALSE),0)) | K8: =IF(A8="",0,ROUND(I8/160*1.25*H8,0)) | L8: =IF(A8="",0,IFERROR(VLOOKUP(A8,'マスタ'!$A:$F,6,FALSE),0)) | N8: =SUM(I8:M8) | U8: =SUM(O8:T8) | V8: =N8-U8
B9: =IF(A9="","",IFERROR(VLOOKUP(A9,'マスタ'!$A:$F,2,FALSE),"")) | C9: =IF(A9="","",IFERROR(VLOOKUP(A9,'マスタ'!$A:$F,3,FALSE),"")) | I9: =IF(A9="",0,IFERROR(VLOOKUP(A9,'マスタ'!$A:$F,4,FALSE),0)) | J9: =IF(A9="",0,IFERROR(VLOOKUP(A9,'マスタ'!$A:$F,5,FALSE),0)) | K9: =IF(A9="",0,ROUND(I9/160*1.25*H9,0)) | L9: =IF(A9="",0,IFERROR(VLOOKUP(A9,'マスタ'!$A:$F,6,FALSE),0)) | N9: =SUM(I9:M9) | U9: =SUM(O9:T9) | V9: =N9-U9
B10: =IF(A10="","",IFERROR(VLOOKUP(A10,'マスタ'!$A:$F,2,FALSE),"")) | C10: =IF(A10="","",IFERROR(VLOOKUP(A10,'マスタ'!$A:$F,3,FALSE),"")) | I10: =IF(A10="",0,IFERROR(VLOOKUP(A10,'マスタ'!$A:$F,4,FALSE),0)) | J10: =IF(A10="",0,IFERROR(VLOOKUP(A10,'マスタ'!$A:$F,5,FALSE),0)) | K10: =IF(A10="",0,ROUND(I10/160*1.25*H10,0)) | L10: =IF(A10="",0,IFERROR(VLOOKUP(A10,'マスタ'!$A:$F,6,FALSE),0)) | N10: =SUM(I10:M10) | U10: =SUM(O10:T10) | V10: =N10-U10
B11: =IF(A11="","",IFERROR(VLOOKUP(A11,'マスタ'!$A:$F,2,FALSE),"")) | C11: =IF(A11="","",IFERROR(VLOOKUP(A11,'マスタ'!$A:$F,3,FALSE),"")) | I11: =IF(A11="",0,IFERROR(VLOOKUP(A11,'マスタ'!$A:$F,4,FALSE),0)) | J11: =IF(A11="",0,IFERROR(VLOOKUP(A11,'マスタ'!$A:$F,5,FALSE),0)) | K11: =IF(A11="",0,ROUND(I11/160*1.25*H11,0)) | L11: =IF(A11="",0,IFERROR(VLOOKUP(A11,'マスタ'!$A:$F,6,FALSE),0)) | N11: =SUM(I11:M11) | U11: =SUM(O11:T11) | V11: =N11-U11
B12: =IF(A12="","",IFERROR(VLOOKUP(A12,'マスタ'!$A:$F,2,FALSE),"")) | C12: =IF(A12="","",IFERROR(VLOOKUP(A12,'マスタ'!$A:$F,3,FALSE),"")) | I12: =IF(A12="",0,IFERROR(VLOOKUP(A12,'マスタ'!$A:$F,4,FALSE),0)) | J12: =IF(A12="",0,IFERROR(VLOOKUP(A12,'マスタ'!$A:$F,5,FALSE),0)) | K12: =IF(A12="",0,ROUND(I12/160*1.25*H12,0)) | L12: =IF(A12="",0,IFERROR(VLOOKUP(A12,'マスタ'!$A:$F,6,FALSE),0)) | N12: =SUM(I12:M12) | U12: =SUM(O12:T12) | V12: =N12-U12
B13: =IF(A13="","",IFERROR(VLOOKUP(A13,'マスタ'!$A:$F,2,FALSE),"")) | C13: =IF(A13="","",IFERROR(VLOOKUP(A13,'マスタ'!$A:$F,3,FALSE),"")) | I13: =IF(A13="",0,IFERROR(VLOOKUP(A13,'マスタ'!$A:$F,4,FALSE),0)) | J13: =IF(A13="",0,IFERROR(VLOOKUP(A13,'マスタ'!$A:$F,5,FALSE),0)) | K13: =IF(A13="",0,ROUND(I13/160*1.25*H13,0)) | L13: =IF(A13="",0,IFERROR(VLOOKUP(A13,'マスタ'!$A:$F,6,FALSE),0)) | N13: =SUM(I13:M13) | U13: =SUM(O13:T13) | V13: =N13-U13
B14: =IF(A14="","",IFERROR(VLOOKUP(A14,'マスタ'!$A:$F,2,FALSE),"")) | C14: =IF(A14="","",IFERROR(VLOOKUP(A14,'マスタ'!$A:$F,3,FALSE),"")) | I14: =IF(A14="",0,IFERROR(VLOOKUP(A14,'マスタ'!$A:$F,4,FALSE),0)) | J14: =IF(A14="",0,IFERROR(VLOOKUP(A14,'マスタ'!$A:$F,5,FALSE),0)) | K14: =IF(A14="",0,ROUND(I14/160*1.25*H14,0)) | L14: =IF(A14="",0,IFERROR(VLOOKUP(A14,'マスタ'!$A:$F,6,FALSE),0)) | N14: =SUM(I14:M14) | U14: =SUM(O14:T14) | V14: =N14-U14
A15: 合 計 | D15: =SUM(D5:D14) | E15: =SUM(E5:E14) | F15: =SUM(F5:F14) | G15: =SUM(G5:G14) | H15: =SUM(H5:H14) | I15: =SUM(I5:I14) | J15: =SUM(J5:J14) | K15: =SUM(K5:K14) | ... V15: =SUM(V5:V14)

Sheet 12月
A1: 給与台帳 12月分
A2: 会社名：株式会社サンプル | L2: 作成日：2026年12月
A3: 基本情報 | D3: 勤 怠 情 報 | I3: 支 給 項 目 | O3: 控 除 項 目 | V3: 差引 支給額
A4: 従業員 番号 | B4: 氏名 | C4: 所属 | D4: 所定 労働日数 | E4: 出勤 日数 | F4: 欠勤 日数 | G4: 有給 取得日数 | H4: 残業 時間 | I4: 基本給 | J4: 役職 手当 | K4: 残業 手当 | L4: 通勤 手当 | M4: その他 手当 | N4: 支給 合計 | O4: 健康 保険 | P4: 厚生 年金 | Q4: 雇用 保険 | R4: 所得税 | S4: 住民税 | T4: その他 控除 | U4: 控除 合計 | V4: 差引 支給額
A5: 001 | B5: =IF(A5="","",IFERROR(VLOOKUP(A5,'マスタ'!$A:$F,2,FALSE),"")) | C5: =IF(A5="","",IFERROR(VLOOKUP(A5,'マスタ'!$A:$F,3,FALSE),"")) | D5: 20 | E5: 20 | F5: 0 | G5: 0 | H5: 10 | I5: =IF(A5="",0,IFERROR(VLOOKUP(A5,'マスタ'!$A:$F,4,FALSE),0)) | J5: =IF(A5="",0,IFERROR(VLOOKUP(A5,'マスタ'!$A:$F,5,FALSE),0)) | K5: =IF(A5="",0,ROUND(I5/160*1.25*H5,0)) | L5: =IF(A5="",0,IFERROR(VLOOKUP(A5,'マスタ'!$A:$F,6,FALSE),0)) | M5: 0 | N5: =SUM(I5:M5) | O5: 17500 | P5: 32490 | Q5: 2100 | R5: 8500 | S5: 12000 | T5: 0 | U5: =SUM(O5:T5) | V5: =N5-U5
A6: 002 | B6: =IF(A6="","",IFERROR(VLOOKUP(A6,'マスタ'!$A:$F,2,FALSE),"")) | C6: =IF(A6="","",IFERROR(VLOOKUP(A6,'マスタ'!$A:$F,3,FALSE),"")) | D6: 20 | E6: 19 | F6: 1 | G6: 1 | H6: 5 | I6: =IF(A6="",0,IFERROR(VLOOKUP(A6,'マスタ'!$A:$F,4,FALSE),0)) | J6: =IF(A6="",0,IFERROR(VLOOKUP(A6,'マスタ'!$A:$F,5,FALSE),0)) | K6: =IF(A6="",0,ROUND(I6/160*1.25*H6,0)) | L6: =IF(A6="",0,IFERROR(VLOOKUP(A6,'マスタ'!$A:$F,6,FALSE),0)) | M6: 0 | N6: =SUM(I6:M6) | O6: 14000 | P6: 25990 | Q6: 1680 | R6: 5500 | S6: 9000 | T6: 0 | U6: =SUM(O6:T6) | V6: =N6-U6
A7: 003 | B7: =IF(A7="","",IFERROR(VLOOKUP(A7,'マスタ'!$A:$F,2,FALSE),"")) | C7: =IF(A7="","",IFERROR(VLOOKUP(A7,'マスタ'!$A:$F,3,FALSE),"")) | D7: 20 | E7: 20 | F7: 0 | G7: 2 | H7: 15 | I7: =IF(A7="",0,IFERROR(VLOOKUP(A7,'マスタ'!$A:$F,4,FALSE),0)) | J7: =IF(A7="",0,IFERROR(VLOOKUP(A7,'マスタ'!$A:$F,5,FALSE),0)) | K7: =IF(A7="",0,ROUND(I7/160*1.25*H7,0)) | L7: =IF(A7="",0,IFERROR(VLOOKUP(A7,'マスタ'!$A:$F,6,FALSE),0)) | M7: 0 | N7: =SUM(I7:M7) | O7: 16000 | P7: 29730 | Q7: 1920 | R7: 7000 | S7: 10500 | T7: 0 | U7: =SUM(O7:T7) | V7: =N7-U7
B8: =IF(A8="","",IFERROR(VLOOKUP(A8,'マスタ'!$A:$F,2,FALSE),"")) | C8: =IF(A8="","",IFERROR(VLOOKUP(A8,'マスタ'!$A:$F,3,FALSE),"")) | I8: =IF(A8="",0,IFERROR(VLOOKUP(A8,'マスタ'!$A:$F,4,FALSE),0)) | J8: =IF(A8="",0,IFERROR(VLOOKUP(A8,'マスタ'!$A:$F,5,FALSE),0)) | K8: =IF(A8="",0,ROUND(I8/160*1.25*H8,0)) | L8: =IF(A8="",0,IFERROR(VLOOKUP(A8,'マスタ'!$A:$F,6,FALSE),0)) | N8: =SUM(I8:M8) | U8: =SUM(O8:T8) | V8: =N8-U8
B9: =IF(A9="","",IFERROR(VLOOKUP(A9,'マスタ'!$A:$F,2,FALSE),"")) | C9: =IF(A9="","",IFERROR(VLOOKUP(A9,'マスタ'!$A:$F,3,FALSE),"")) | I9: =IF(A9="",0,IFERROR(VLOOKUP(A9,'マスタ'!$A:$F,4,FALSE),0)) | J9: =IF(A9="",0,IFERROR(VLOOKUP(A9,'マスタ'!$A:$F,5,FALSE),0)) | K9: =IF(A9="",0,ROUND(I9/160*1.25*H9,0)) | L9: =IF(A9="",0,IFERROR(VLOOKUP(A9,'マスタ'!$A:$F,6,FALSE),0)) | N9: =SUM(I9:M9) | U9: =SUM(O9:T9) | V9: =N9-U9
B10: =IF(A10="","",IFERROR(VLOOKUP(A10,'マスタ'!$A:$F,2,FALSE),"")) | C10: =IF(A10="","",IFERROR(VLOOKUP(A10,'マスタ'!$A:$F,3,FALSE),"")) | I10: =IF(A10="",0,IFERROR(VLOOKUP(A10,'マスタ'!$A:$F,4,FALSE),0)) | J10: =IF(A10="",0,IFERROR(VLOOKUP(A10,'マスタ'!$A:$F,5,FALSE),0)) | K10: =IF(A10="",0,ROUND(I10/160*1.25*H10,0)) | L10: =IF(A10="",0,IFERROR(VLOOKUP(A10,'マスタ'!$A:$F,6,FALSE),0)) | N10: =SUM(I10:M10) | U10: =SUM(O10:T10) | V10: =N10-U10
